Workbook

Sheet Semana 1
E1: 1 | G1: 2 | H1: 3 | I1: 4 | J1: 5 | K1: 6 | L1: 7 | M1: 8 | N1: 9 | O1: 10 | P1: 11 | Q1: 48 | R1: 49 | S1: 50 | T1: 51 | U1: 52 | V1: 53 | W1: 54 | X1: 55 | Y1: 56 | Z1: 57 | AA1: 58 | AB1: 59 | AC1: 60 | AD1: 61
E2: Servicio al cliente
B3: # | C3: Produc | D3: Codigo | E3: Requerimiento | H3: Lunes | Q3: Sabado
E4: Scheduled | H4: Horario | J4: Almuerzo | L4: Break 1 | N4: Break 2 | Q4: Horario | S4: Almuerzo | U4: Break 1 | W4: Break 2
E5: Over / Under | F5: Semana 1 | G5: Skill | H5: 1 Entrada Lunes | I5: 1 Salida Lunes | J5: 1 Inicio Almuerzo Lunes | K5: 1 Termina Almuerzo Lunes | L5: 1 Incio Break 1 Lunes | M5: 1 Termina Break 1 Lunes | N5: 1 Incio Break 2 Lunes | O5: 1 Termina Break 2 Lunes | P5: 1 Horas Lunes | Q5: 1 Entrada Sabado | R5: 1 Salida Sabado | S5: 1 Inicio AlmuerzoSabado | T5: 1 Termina Almuerzo Sabado | U5: 1 Incio Break 1 Sabado | V5: 1 Termina Break 1 Sabado | W5: 1 Incio Break 2 Sabado | X5: 1 Termina Break 2 Sabado | Y5: 1 Horas Sabado | Z5: 1 Horas Martes | AA5: 1 Horas Miercoles | AB5: 1 Horas Jueves | AC5: 1 Horas Viernes | AD5: 1 Horas Semanales
B6: 1 | C6: Si | E6: =Personal!G6 -> Nancy Beatriz Pedroza | F6: Semana 1 | G6: =Personal!H6 -> AGENTE | H6: 0.70833333 | I6: 1 | J6: 0.79166667 | K6: 0.8125 | L6: 0.8125 | M6: =IF(G6="AGENTE",'Semana 1'!$L6+0.014,IF(G6="REDES",'Semana 1'!$L6+0.014,IF(G6="AGENTE RM",'Semana 1'!$L6+0.014,IF(G6="AGENTE APERTURA",'Semana 1'!$L6+0.014,IF(G6="AGENTE CIERRE",'Semana 1'!$L6+0.014," - "))))) -> 19:50 | N6: 0.82638889 | O6: =IF(G6="AGENTE",'Semana 1'!$N6+0.007,IF(G6="REDES",'Semana 1'!$N6+0.007,IF(G6="AGENTE RM",'Semana 1'!$N6+0.007,IF(G6="AGENTE APERTURA",'Semana 1'!$N6+0.007,IF(G6="AGENTE CIERRE",'Semana 1'!$N6+0.007," - "))))) -> 20:00 | P6: =(IFERROR(I6-H6,0)*24)-1 -> 6.0 | Q6: 0.70833333 | R6: 1 | S6: 0.79166667 | T6: 0.8125 | U6: 0.8125 | V6: 0.8265 | W6: 0.82638889 | X6: 0.83338889 | Y6: =(IFERROR(R6-Q6,0)*24)-1 -> 6.0 | Z6: =$P6 -> 6.0 | AA6: =$P6 -> 6.0 | AB6: =$P6 -> 6.0 | AC6: =$P6 -> 6.0 | AD6: =P6+Z6+AA6+AB6+AC6+Y6 -> 36
B7: 2 | C7: Si | E7: =Personal!G7 -> Carina Alejandra Peliz Reban | F7: Semana 1 | G7: =Personal!H7 -> REDES | H7: 0.375 | I7: =IF(H7=0," ",IF(Q7=0,(H7+0.417),(H7+0.3756))) -> 18:00 | J7: 0.5 | K7: =IF(G7="AGENTE",'Semana 1'!$J7+0.042,IF(G7="REDES",'Semana 1'!$J7+0.042,IF(G7="AGENTE RM",'Semana 1'!$J7+0.042,IF(G7="AGENTE APERTURA",'Semana 1'!$J7+0.021,IF(G7="AGENTE CIERRE",'Semana 1'!$J7+0.021," - "))))) -> 13:00 | L7: 0.41666667 | M7: =IF(G7="AGENTE",'Semana 1'!$L7+0.014,IF(G7="REDES",'Semana 1'!$L7+0.014,IF(G7="AGENTE RM",'Semana 1'!$L7+0.014,IF(G7="AGENTE APERTURA",'Semana 1'!$L7+0.014,IF(G7="AGENTE CIERRE",'Semana 1'!$L7+0.014," - "))))) -> 10:20 | N7: 0.64583333 | O7: =IF(G7="AGENTE",'Semana 1'!$N7+0.007,IF(G7="REDES",'Semana 1'!$N7+0.007,IF(G7="AGENTE RM",'Semana 1'!$N7+0.007,IF(G7="AGENTE APERTURA",'Semana 1'!$N7+0.007,IF(G7="AGENTE CIERRE",'Semana 1'!$N7+0.007," - "))))) -> 15:40 | P7: =(IFERROR(I7-H7,0)*24)-1 -> 8.0 | Q7: 0.41666667 | R7: =IF(Q7=0,"",Q7+0.209) -> 15:00 | U7: 0.4375 | V7: =IF(U7=0,"",U7+0.021) -> 11:00 | Y7: =(IFERROR(R7-Q7,0)*24) -> 5.0 | Z7: =$P7 -> 8.0 | AA7: =$P7 -> 8.0 | AB7: =$P7 -> 8.0 | AC7: =$P7 -> 8.0 | AD7: =P7+Z7+AA7+AB7+AC7+Y7 -> 45
B8: 3 | C8: No | E8: =Personal!G8 -> - | F8: Semana 1 | G8: =Personal!H8 -> - | I8: =IF(H8=0," ",IF(Q8=0,(H8+0.417),(H8+0.3756))) | K8: =IF(G8="AGENTE",'Semana 1'!$J8+0.042,IF(G8="REDES",'Semana 1'!$J8+0.042,IF(G8="AGENTE RM",'Semana 1'!$J8+0.042,IF(G8="AGENTE APERTURA",'Semana 1'!$J8+0.021,IF(G8="AGENTE CIERRE",'Semana 1'!$J8+0.021," - "))))) -> - | M8: =IF(G8="AGENTE",'Semana 1'!$L8+0.014,IF(G8="REDES",'Semana 1'!$L8+0.014,IF(G8="AGENTE RM",'Semana 1'!$L8+0.014,IF(G8="AGENTE APERTURA",'Semana 1'!$L8+0.014,IF(G8="AGENTE CIERRE",'Semana 1'!$L8+0.014," - "))))) -> - | O8: =IF(G8="AGENTE",'Semana 1'!$N8+0.007,IF(G8="REDES",'Semana 1'!$N8+0.007,IF(G8="AGENTE RM",'Semana 1'!$N8+0.007,IF(G8="AGENTE APERTURA",'Semana 1'!$N8+0.007,IF(G8="AGENTE CIERRE",'Semana 1'!$N8+0.007," - "))))) -> - | P8: =(IFERROR(I8-H8,0)*24)-1 -> -1.0 | V8: =IF(U8=0,"",U8+0.021) | Y8: =(IFERROR(R8-Q8,0)*24) -> 0.0 | Z8: =$P8 -> -1.0 | AA8: =$P8 -> -1.0 | AB8: =$P8 -> -1.0 | AC8: =$P8 -> -1.0 | AD8: =P8+Z8+AA8+AB8+AC8+Y8 -> -5
B9: 4 | C9: Si | E9: =Personal!G9 -> Daisy Yomara Mateo | F9: Semana 1 | G9: =Personal!H9 -> SOPORTE | I9: =IF(H9=0," ",IF(Q9=0,(H9+0.417),(H9+0.3756))) | K9: =IF(G9="AGENTE",'Semana 1'!$J9+0.042,IF(G9="REDES",'Semana 1'!$J9+0.042,IF(G9="AGENTE RM",'Semana 1'!$J9+0.042,IF(G9="AGENTE APERTURA",'Semana 1'!$J9+0.021,IF(G9="AGENTE CIERRE",'Semana 1'!$J9+0.021," - "))))) -> - | M9: =IF(G9="AGENTE",'Semana 1'!$L9+0.014,IF(G9="REDES",'Semana 1'!$L9+0.014,IF(G9="AGENTE RM",'Semana 1'!$L9+0.014,IF(G9="AGENTE APERTURA",'Semana 1'!$L9+0.014,IF(G9="AGENTE CIERRE",'Semana 1'!$L9+0.014," - "))))) -> - | O9: =IF(G9="AGENTE",'Semana 1'!$N9+0.007,IF(G9="REDES",'Semana 1'!$N9+0.007,IF(G9="AGENTE RM",'Semana 1'!$N9+0.007,IF(G9="AGENTE APERTURA",'Semana 1'!$N9+0.007,IF(G9="AGENTE CIERRE",'Semana 1'!$N9+0.007," - "))))) -> - | P9: =(IFERROR(I9-H9,0)*24)-1 -> -1.0 | R9: =IF(Q9=0,"",Q9+0.209) | V9: =IF(U9=0,"",U9+0.021) | Y9: =(IFERROR(R9-Q9,0)*24) -> 0.0 | Z9: =$P9 -> -1.0 | AA9: =$P9 -> -1.0 | AB9: =$P9 -> -1.0 | AC9: =$P9 -> -1.0 | AD9: =P9+Z9+AA9+AB9+AC9+Y9 -> -5
B10: 5 | C10: Si | E10: =Personal!G10 -> Carlo Giordiano Caballero Morales | F10: Semana 1 | G10: =Personal!H10 -> REDES | H10: 0.29166667 | I10: =IF(H10=0," ",IF(Q10=0,(H10+0.417),(H10+0.3756))) -> 16:00 | J10: 0.54166667 | K10: =IF(G10="AGENTE",'Semana 1'!$J10+0.042,IF(G10="REDES",'Semana 1'!$J10+0.042,IF(G10="AGENTE RM",'Semana 1'!$J10+0.042,IF(G10="AGENTE APERTURA",'Semana 1'!$J10+0.021,IF(G10="AGENTE CIERRE",'Semana 1'!$J10+0.021," - "))))) -> 14:00 | L10: 0.36111111 | M10: =IF(G10="AGENTE",'Semana 1'!$L10+0.014,IF(G10="REDES",'Semana 1'!$L10+0.014,IF(G10="AGENTE RM",'Semana 1'!$L10+0.014,IF(G10="AGENTE APERTURA",'Semana 1'!$L10+0.014,IF(G10="AGENTE CIERRE",'Semana 1'!$L10+0.014," - "))))) -> 9:00 | N10: 0.59722222 | O10: =IF(G10="AGENTE",'Semana 1'!$N10+0.007,IF(G10="REDES",'Semana 1'!$N10+0.007,IF(G10="AGENTE RM",'Semana 1'!$N10+0.007,IF(G10="AGENTE APERTURA",'Semana 1'!$N10+0.007,IF(G10="AGENTE CIERRE",'Semana 1'!$N10+0.007," - "))))) -> 14:30 | P10: =(IFERROR(I10-H10,0)*24)-1 -> 8.0 | Q10: 0.35416667 | R10: =IF(Q10=0,"",Q10+0.209) -> 13:30 | U10: 0.375 | V10: =IF(U10=0,"",U10+0.021) -> 9:30 | Y10: =(IFERROR(R10-Q10,0)*24) -> 5.0 | Z10: =$P10 -> 8.0 | AA10: =$P10 -> 8.0 | AB10: =$P10 -> 8.0 | AC10: =$P10 -> 8.0 | AD10: =P10+Z10+AA10+AB10+AC10+Y10 -> 45
B11: 6 | C11: Si | E11: =Personal!G11 -> Ani Rubi Lucero Gonzalez | F11: Semana 1 | G11: =Personal!H11 -> SOPORTE | I11: =IF(H11=0," ",IF(Q11=0,(H11+0.417),(H11+0.3756))) | K11: =IF(G11="AGENTE",'Semana 1'!$J11+0.042,IF(G11="REDES",'Semana 1'!$J11+0.042,IF(G11="AGENTE RM",'Semana 1'!$J11+0.042,IF(G11="AGENTE APERTURA",'Semana 1'!$J11+0.021,IF(G11="AGENTE CIERRE",'Semana 1'!$J11+0.021," - "))))) -> - | M11: =IF(G11="AGENTE",'Semana 1'!$L11+0.014,IF(G11="REDES",'Semana 1'!$L11+0.014,IF(G11="AGENTE RM",'Semana 1'!$L11+0.014,IF(G11="AGENTE APERTURA",'Semana 1'!$L11+0.014,IF(G11="AGENTE CIERRE",'Semana 1'!$L11+0.014," - "))))) -> - | O11: =IF(G11="AGENTE",'Semana 1'!$N11+0.007,IF(G11="REDES",'Semana 1'!$N11+0.007,IF(G11="AGENTE RM",'Semana 1'!$N11+0.007,IF(G11="AGENTE APERTURA",'Semana 1'!$N11+0.007,IF(G11="AGENTE CIERRE",'Semana 1'!$N11+0.007," - "))))) -> - | P11: =(IFERROR(I11-H11,0)*24)-1 -> -1.0 | R11: =IF(Q11=0,"",Q11+0.209) | Y11: =(IFERROR(R11-Q11,0)*24) -> 0.0 | Z11: =$P11 -> -1.0 | AA11: =$P11 -> -1.0 | AB11: =$P11 -> -1.0 | AC11: =$P11 -> -1.0 | AD11: =P11+Z11+AA11+AB11+AC11+Y11 -> -5
B12: 7 | C12: Si | E12: =Personal!G12 -> Hilda Sofia Gonzalez De León | F12: Semana 1 | G12: =Personal!H12 -> REDES | H12: 0.375 | I12: =IF(H12=0," ",IF(Q12=0,(H12+0.417),(H12+0.3756))) -> 18:00 | J12: 0.5 | K12: =IF(G12="AGENTE",'Semana 1'!$J12+0.042,IF(G12="REDES",'Semana 1'!$J12+0.042,IF(G12="AGENTE RM",'Semana 1'!$J12+0.042,IF(G12="AGENTE APERTURA",'Semana 1'!$J12+0.021,IF(G12="AGENTE CIERRE",'Semana 1'!$J12+0.021," - "))))) -> 13:00 | L12: 0.43055556 | M12: =IF(G12="AGENTE",'Semana 1'!$L12+0.014,IF(G12="REDES",'Semana 1'!$L12+0.014,IF(G12="AGENTE RM",'Semana 1'!$L12+0.014,IF(G12="AGENTE APERTURA",'Semana 1'!$L12+0.014,IF(G12="AGENTE CIERRE",'Semana 1'!$L12+0.014," - "))))) -> 10:40 | N12: 0.65277778 | O12: =IF(G12="AGENTE",'Semana 1'!$N12+0.007,IF(G12="REDES",'Semana 1'!$N12+0.007,IF(G12="AGENTE RM",'Semana 1'!$N12+0.007,IF(G12="AGENTE APERTURA",'Semana 1'!$N12+0.007,IF(G12="AGENTE CIERRE",'Semana 1'!$N12+0.007," - "))))) -> 15:50 | P12: =(IFERROR(I12-H12,0)*24)-1 -> 8.0 | Q12: 0.375 | R12: =IF(Q12=0,"",Q12+0.209) -> 14:00 | U12: 0.39583333 | V12: =IF(U12=0,"",U12+0.021) -> 10:00 | Y12: =(IFERROR(R12-Q12,0)*24) -> 5.0 | Z12: =$P12 -> 8.0 | AA12: =$P12 -> 8.0 | AB12: =$P12 -> 8.0 | AC12: =$P12 -> 8.0 | AD12: =P12+Z12+AA12+AB12+AC12+Y12 -> 45
B13: 8 | C13: No | E13: =Personal!G13 -> - | F13: Semana 1 | G13: =Personal!H13 -> - | I13: =IF(H13=0," ",IF(Q13=0,(H13+0.417),(H13+0.3756))) | K13: =IF(G13="AGENTE",'Semana 1'!$J13+0.042,IF(G13="REDES",'Semana 1'!$J13+0.042,IF(G13="AGENTE RM",'Semana 1'!$J13+0.042,IF(G13="AGENTE APERTURA",'Semana 1'!$J13+0.021,IF(G13="AGENTE CIERRE",'Semana 1'!$J13+0.021," - "))))) -> - | M13: =IF(G13="AGENTE",'Semana 1'!$L13+0.014,IF(G13="REDES",'Semana 1'!$L13+0.014,IF(G13="AGENTE RM",'Semana 1'!$L13+0.014,IF(G13="AGENTE APERTURA",'Semana 1'!$L13+0.014,IF(G13="AGENTE CIERRE",'Semana 1'!$L13+0.014," - "))))) -> - | O13: =IF(G13="AGENTE",'Semana 1'!$N13+0.007,IF(G13="REDES",'Semana 1'!$N13+0.007,IF(G13="AGENTE RM",'Semana 1'!$N13+0.007,IF(G13="AGENTE APERTURA",'Semana 1'!$N13+0.007,IF(G13="AGENTE CIERRE",'Semana 1'!$N13+0.007," - "))))) -> - | P13: =(IFERROR(I13-H13,0)*24)-1 -> -1.0 | R13: =IF(Q13=0,"",Q13+0.209) | V13: =IF(U13=0,"",U13+0.021) | Y13: =(IFERROR(R13-Q13,0)*24) -> 0.0 | Z13: =$P13 -> -1.0 | AA13: =$P13 -> -1.0 | AB13: =$P13 -> -1.0 | AC13: =$P13 -> -1.0 | AD13: =P13+Z13+AA13+AB13+AC13+Y13 -> -5
B14: 9 | C14: Si | E14: =Personal!G14 -> Jorge Israel Reyes Valencia | F14: Semana 1 | G14: =Personal!H14 -> SOPORTE | I14: =IF(H14=0," ",IF(Q14=0,(H14+0.417),(H14+0.3756))) | K14: =IF(G14="AGENTE",'Semana 1'!$J14+0.042,IF(G14="REDES",'Semana 1'!$J14+0.042,IF(G14="AGENTE RM",'Semana 1'!$J14+0.042,IF(G14="AGENTE APERTURA",'Semana 1'!$J14+0.021,IF(G14="AGENTE CIERRE",'Semana 1'!$J14+0.021," - "))))) -> - | M14: =IF(G14="AGENTE",'Semana 1'!$L14+0.014,IF(G14="REDES",'Semana 1'!$L14+0.014,IF(G14="AGENTE RM",'Semana 1'!$L14+0.014,IF(G14="AGENTE APERTURA",'Semana 1'!$L14+0.014,IF(G14="AGENTE CIERRE",'Semana 1'!$L14+0.014," - "))))) -> - | O14: =IF(G14="AGENTE",'Semana 1'!$N14+0.007,IF(G14="REDES",'Semana 1'!$N14+0.007,IF(G14="AGENTE RM",'Semana 1'!$N14+0.007,IF(G14="AGENTE APERTURA",'Semana 1'!$N14+0.007,IF(G14="AGENTE CIERRE",'Semana 1'!$N14+0.007," - "))))) -> - | P14: =(IFERROR(I14-H14,0)*24)-1 -> -1.0 | R14: =IF(Q14=0,"",Q14+0.209) | T14: =IF(S14=0,"",S14+0.021) | V14: =IF(U14=0,"",U14+0.01) | X14: =IF(W14=0,"",W14+0.01) | Y14: =(IFERROR(R14-Q14,0)*24) -> 0.0 | Z14: =$P14 -> -1.0 | AA14: =$P14 -> -1.0 | AB14: =$P14 -> -1.0 | AC14: =$P14 -> -1.0 | AD14: =P14+Z14+AA14+AB14+AC14+Y14 -> -5
B15: 10 | C15: Si | E15: =Personal!G15 -> Marcos Geovanny Coronado Giron | F15: Semana 1 | G15: =Personal!H15 -> SOPORTE | I15: =IF(H15=0," ",IF(Q15=0,(H15+0.417),(H15+0.3756))) | K15: =IF(G15="AGENTE",'Semana 1'!$J15+0.042,IF(G15="REDES",'Semana 1'!$J15+0.042,IF(G15="AGENTE RM",'Semana 1'!$J15+0.042,IF(G15="AGENTE APERTURA",'Semana 1'!$J15+0.021,IF(G15="AGENTE CIERRE",'Semana 1'!$J15+0.021," - "))))) -> - | M15: =IF(G15="AGENTE",'Semana 1'!$L15+0.014,IF(G15="REDES",'Semana 1'!$L15+0.014,IF(G15="AGENTE RM",'Semana 1'!$L15+0.014,IF(G15="AGENTE APERTURA",'Semana 1'!$L15+0.014,IF(G15="AGENTE CIERRE",'Semana 1'!$L15+0.014," - "))))) -> - | O15: =IF(G15="AGENTE",'Semana 1'!$N15+0.007,IF(G15="REDES",'Semana 1'!$N15+0.007,IF(G15="AGENTE RM",'Semana 1'!$N15+0.007,IF(G15="AGENTE APERTURA",'Semana 1'!$N15+0.007,IF(G15="AGENTE CIERRE",'Semana 1'!$N15+0.007," - "))))) -> - | P15: =(IFERROR(I15-H15,0)*24)-1 -> -1.0 | R15: =IF(Q15=0,"",Q15+0.209) | Y15: =(IFERROR(R15-Q15,0)*24) -> 0.0 | Z15: =$P15 -> -1.0 | AA15: =$P15 -> -1.0 | AB15: =$P15 -> -1.0 | AC15: =$P15 -> -1.0 | AD15: =P15+Z15+AA15+AB15+AC15+Y15 -> -5
B16: 11 | C16: Si | E16: =Personal!G16 -> Anyely Eunice Florian Florian | F16: Semana 1 | G16: =Personal!H16 -> SOPORTE | I16: =IF(H16=0," ",IF(Q16=0,(H16+0.417),(H16+0.3756))) | K16: =IF(G16="AGENTE",'Semana 1'!$J16+0.042,IF(G16="REDES",'Semana 1'!$J16+0.042,IF(G16="AGENTE RM",'Semana 1'!$J16+0.042,IF(G16="AGENTE APERTURA",'Semana 1'!$J16+0.021,IF(G16="AGENTE CIERRE",'Semana 1'!$J16+0.021," - "))))) -> - | M16: =IF(G16="AGENTE",'Semana 1'!$L16+0.014,IF(G16="REDES",'Semana 1'!$L16+0.014,IF(G16="AGENTE RM",'Semana 1'!$L16+0.014,IF(G16="AGENTE APERTURA",'Semana 1'!$L16+0.014,IF(G16="AGENTE CIERRE",'Semana 1'!$L16+0.014," - "))))) -> - | O16: =IF(G16="AGENTE",'Semana 1'!$N16+0.007,IF(G16="REDES",'Semana 1'!$N16+0.007,IF(G16="AGENTE RM",'Semana 1'!$N16+0.007,IF(G16="AGENTE APERTURA",'Semana 1'!$N16+0.007,IF(G16="AGENTE CIERRE",'Semana 1'!$N16+0.007," - "))))) -> - | P16: =(IFERROR(I16-H16,0)*24)-1 -> -1.0 | R16: =IF(Q16=0,"",Q16+0.209) | V16: =IF(U16=0,"",U16+0.021) | X16: =IF(W16=0,"",W16+0.021) | Y16: =(IFERROR(R16-Q16,0)*24) -> 0.0 | Z16: =$P16 -> -1.0 | AA16: =$P16 -> -1.0 | AB16: =$P16 -> -1.0 | AC16: =$P16 -> -1.0 | AD16: =P16+Z16+AA16+AB16+AC16+Y16 -> -5
B17: 12 | C17: Si | E17: =Personal!G17 -> Jennifer Alicia Boror Rodriguez | F17: Semana 1 | G17: =Personal!H17 -> REDES | H17: 0.27083333 | I17: =IF(H17=0," ",IF(Q17=0,(H17+0.417),(H17+0.3756))) -> 15:30 | J17: 0.54166667 | K17: =IF(G17="AGENTE",'Semana 1'!$J17+0.042,IF(G17="REDES",'Semana 1'!$J17+0.042,IF(G17="AGENTE RM",'Semana 1'!$J17+0.042,IF(G17="AGENTE APERTURA",'Semana 1'!$J17+0.021,IF(G17="AGENTE CIERRE",'Semana 1'!$J17+0.021," - "))))) -> 14:00 | L17: 0.34722222 | M17: =IF(G17="AGENTE",'Semana 1'!$L17+0.014,IF(G17="REDES",'Semana 1'!$L17+0.014,IF(G17="AGENTE RM",'Semana 1'!$L17+0.014,IF(G17="AGENTE APERTURA",'Semana 1'!$L17+0.014,IF(G17="AGENTE CIERRE",'Semana 1'!$L17+0.014," - "))))) -> 8:40 | N17: 0.59027778 | O17: =IF(G17="AGENTE",'Semana 1'!$N17+0.007,IF(G17="REDES",'Semana 1'!$N17+0.007,IF(G17="AGENTE RM",'Semana 1'!$N17+0.007,IF(G17="AGENTE APERTURA",'Semana 1'!$N17+0.007,IF(G17="AGENTE CIERRE",'Semana 1'!$N17+0.007," - "))))) -> 14:20 | P17: =(IFERROR(I17-H17,0)*24)-1 -> 8.0 | Q17: 0.27083333 | R17: =IF(Q17=0,"",Q17+0.209) -> 11:30 | U17: 0.3125 | V17: =IF(U17=0,"",U17+0.021) -> 8:00 | Y17: =(IFERROR(R17-Q17,0)*24) -> 5.0 | Z17: =$P17 -> 8.0 | AA17: =$P17 -> 8.0 | AB17: =$P17 -> 8.0 | AC17: =$P17 -> 8.0 | AD17: =P17+Z17+AA17+AB17+AC17+Y17 -> 45
B18: 13 | C18: No | E18: =Personal!G18 -> - | F18: Semana 1 | G18: =Personal!H18 -> - | I18: =IF(H18=0," ",IF(Q18=0,(H18+0.417),(H18+0.3756))) | K18: =IF(G18="AGENTE",'Semana 1'!$J18+0.042,IF(G18="REDES",'Semana 1'!$J18+0.042,IF(G18="AGENTE RM",'Semana 1'!$J18+0.042,IF(G18="AGENTE APERTURA",'Semana 1'!$J18+0.021,IF(G18="AGENTE CIERRE",'Semana 1'!$J18+0.021," - "))))) -> - | M18: =IF(G18="AGENTE",'Semana 1'!$L18+0.014,IF(G18="REDES",'Semana 1'!$L18+0.014,IF(G18="AGENTE RM",'Semana 1'!$L18+0.014,IF(G18="AGENTE APERTURA",'Semana 1'!$L18+0.014,IF(G18="AGENTE CIERRE",'Semana 1'!$L18+0.014," - "))))) -> - | O18: =IF(G18="AGENTE",'Semana 1'!$N18+0.007,IF(G18="REDES",'Semana 1'!$N18+0.007,IF(G18="AGENTE RM",'Semana 1'!$N18+0.007,IF(G18="AGENTE APERTURA",'Semana 1'!$N18+0.007,IF(G18="AGENTE CIERRE",'Semana 1'!$N18+0.007," - "))))) -> - | P18: =(IFERROR(I18-H18,0)*24)-1 -> -1.0 | R18: =IF(Q18=0,"",Q18+0.209) | V18: =IF(U18=0,"",U18+0.021) | Y18: =(IFERROR(R18-Q18,0)*24) -> 0.0 | Z18: =$P18 -> -1.0 | AA18: =$P18 -> -1.0 | AB18: =$P18 -> -1.0 | AC18: =$P18 -> -1.0 | AD18: =P18+Z18+AA18+AB18+AC18+Y18 -> -5
B19: 14 | C19: Si | E19: =Personal!G19 -> Juan José Puluc Chaicoj | F19: Semana 1 | G19: =Personal!H19 -> SOPORTE | I19: =IF(H19=0," ",IF(Q19=0,(H19+0.417),(H19+0.3756))) | K19: =IF(G19="AGENTE",'Semana 1'!$J19+0.042,IF(G19="REDES",'Semana 1'!$J19+0.042,IF(G19="AGENTE RM",'Semana 1'!$J19+0.042,IF(G19="AGENTE APERTURA",'Semana 1'!$J19+0.021,IF(G19="AGENTE CIERRE",'Semana 1'!$J19+0.021," - "))))) -> - | M19: =IF(G19="AGENTE",'Semana 1'!$L19+0.014,IF(G19="REDES",'Semana 1'!$L19+0.014,IF(G19="AGENTE RM",'Semana 1'!$L19+0.014,IF(G19="AGENTE APERTURA",'Semana 1'!$L19+0.014,IF(G19="AGENTE CIERRE",'Semana 1'!$L19+0.014," - "))))) -> - | O19: =IF(G19="AGENTE",'Semana 1'!$N19+0.007,IF(G19="REDES",'Semana 1'!$N19+0.007,IF(G19="AGENTE RM",'Semana 1'!$N19+0.007,IF(G19="AGENTE APERTURA",'Semana 1'!$N19+0.007,IF(G19="AGENTE CIERRE",'Semana 1'!$N19+0.007," - "))))) -> - | P19: =(IFERROR(I19-H19,0)*24)-1 -> -1.0 | R19: =IF(Q19=0,"",Q19+0.209) | Y19: =(IFERROR(R19-Q19,0)*24) -> 0.0 | Z19: =$P19 -> -1.0 | AA19: =$P19 -> -1.0 | AB19: =$P19 -> -1.0 | AC19: =$P19 -> -1.0 | AD19: =P19+Z19+AA19+AB19+AC19+Y19 -> -5
B20: 15 | C20: Si | E20: =Personal!G20 -> Lydicen Anabelly Navarijo Padilla | F20: Semana 1 | G20: =Personal!H20 -> AGENTE RM | H20: 0.375 | I20: =IF(H20=0," ",IF(Q20=0,(H20+0.417),(H20+0.3756))) -> 18:00 | J20: 0.58333333 | K20: =IF(G20="AGENTE",'Semana 1'!$J20+0.042,IF(G20="REDES",'Semana 1'!$J20+0.042,IF(G20="AGENTE RM",'Semana 1'!$J20+0.042,IF(G20="AGENTE APERTURA",'Semana 1'!$J20+0.021,IF(G20="AGENTE CIERRE",'Semana 1'!$J20+0.021," - "))))) -> 15:00 | L20: 0.39583333 | M20: =IF(G20="AGENTE",'Semana 1'!$L20+0.014,IF(G20="REDES",'Semana 1'!$L20+0.014,IF(G20="AGENTE RM",'Semana 1'!$L20+0.014,IF(G20="AGENTE APERTURA",'Semana 1'!$L20+0.014,IF(G20="AGENTE CIERRE",'Semana 1'!$L20+0.014," - "))))) -> 9:50 | N20: 0.66666667 | O20: =IF(G20="AGENTE",'Semana 1'!$N20+0.007,IF(G20="REDES",'Semana 1'!$N20+0.007,IF(G20="AGENTE RM",'Semana 1'!$N20+0.007,IF(G20="AGENTE APERTURA",'Semana 1'!$N20+0.007,IF(G20="AGENTE CIERRE",'Semana 1'!$N20+0.007," - "))))) -> 16:10 | P20: =(IFERROR(I20-H20,0)*24)-1 -> 8.0 | Q20: 0.41666667 | R20: =IF(Q20=0,"",Q20+0.209) -> 15:00 | U20: 0.4375 | V20: =IF(U20=0,"",U20+0.021) -> 11:00 | Y20: =(IFERROR(R20-Q20,0)*24) -> 5.0 | Z20: =$P20 -> 8.0 | AA20: =$P20 -> 8.0 | AB20: =$P20 -> 8.0 | AC20: =$P20 -> 8.0 | AD20: =P20+Z20+AA20+AB20+AC20+Y20 -> 45
B21: 16 | C21: Si | E21: =Personal!G21 -> Cindy Melissa Aroche Ortiz | F21: Semana 1 | G21: =Personal!H21 -> CONTROL | I21: =IF(H21=0," ",IF(Q21=0,(H21+0.417),(H21+0.3756))) | K21: =IF(G21="AGENTE",'Semana 1'!$J21+0.042,IF(G21="REDES",'Semana 1'!$J21+0.042,IF(G21="AGENTE RM",'Semana 1'!$J21+0.042,IF(G21="AGENTE APERTURA",'Semana 1'!$J21+0.021,IF(G21="AGENTE CIERRE",'Semana 1'!$J21+0.021," - "))))) -> - | M21: =IF(G21="AGENTE",'Semana 1'!$L21+0.014,IF(G21="REDES",'Semana 1'!$L21+0.014,IF(G21="AGENTE RM",'Semana 1'!$L21+0.014,IF(G21="AGENTE APERTURA",'Semana 1'!$L21+0.014,IF(G21="AGENTE CIERRE",'Semana 1'!$L21+0.014," - "))))) -> - | O21: =IF(G21="AGENTE",'Semana 1'!$N21+0.007,IF(G21="REDES",'Semana 1'!$N21+0.007,IF(G21="AGENTE RM",'Semana 1'!$N21+0.007,IF(G21="AGENTE APERTURA",'Semana 1'!$N21+0.007,IF(G21="AGENTE CIERRE",'Semana 1'!$N21+0.007," - "))))) -> - | P21: =(IFERROR(I21-H21,0)*24)-1 -> -1.0 | R21: =IF(Q21=0,"",Q21+0.209) | V21: =IF(U21=0,"",U21+0.021) | Y21: =(IFERROR(R21-Q21,0)*24) -> 0.0 | Z21: =$P21 -> -1.0 | AA21: =$P21 -> -1.0 | AB21: =$P21 -> -1.0 | AC21: =$P21 -> -1.0 | AD21: =P21+Z21+AA21+AB21+AC21+Y21 -> -5
B22: 17 | C22: Si | E22: =Personal!G22 -> Katherin Gabriela Monzon Vivar | F22: Semana 1 | G22: =Personal!H22 -> AGENTE | H22: 0.33333333 | I22: =IF(H22=0," ",IF(Q22=0,(H22+0.417),(H22+0.3756))) -> 17:00 | J22: 0.5625 | K22: =IF(G22="AGENTE",'Semana 1'!$J22+0.042,IF(G22="REDES",'Semana 1'!$J22+0.042,IF(G22="AGENTE RM",'Semana 1'!$J22+0.042,IF(G22="AGENTE APERTURA",'Semana 1'!$J22+0.021,IF(G22="AGENTE CIERRE",'Semana 1'!$J22+0.021," - "))))) -> 14:30 | L22: 0.38541667 | M22: =IF(G22="AGENTE",'Semana 1'!$L22+0.014,IF(G22="REDES",'Semana 1'!$L22+0.014,IF(G22="AGENTE RM",'Semana 1'!$L22+0.014,IF(G22="AGENTE APERTURA",'Semana 1'!$L22+0.014,IF(G22="AGENTE CIERRE",'Semana 1'!$L22+0.014," - "))))) -> 9:35 | N22: 0.69791667 | O22: =IF(G22="AGENTE",'Semana 1'!$N22+0.007,IF(G22="REDES",'Semana 1'!$N22+0.007,IF(G22="AGENTE RM",'Semana 1'!$N22+0.007,IF(G22="AGENTE APERTURA",'Semana 1'!$N22+0.007,IF(G22="AGENTE CIERRE",'Semana 1'!$N22+0.007," - "))))) -> 16:55 | P22: =(IFERROR(I22-H22,0)*24)-1 -> 8.0 | Q22: 0.33333333 | R22: =IF(Q22=0,"",Q22+0.209) -> 13:00 | U22: 0.35416667 | V22: =IF(U22=0,"",U22+0.021) -> 9:00 | Y22: =(IFERROR(R22-Q22,0)*24) -> 5.0 | Z22: =$P22 -> 8.0 | AA22: =$P22 -> 8.0 | AB22: =$P22 -> 8.0 | AC22: =$P22 -> 8.0 | AD22: =P22+Z22+AA22+AB22+AC22+Y22 -> 45
B23: 18 | C23: Si | E23: =Personal!G23 -> Velvet Esmeralda Quiroz Godinez | F23: Semana 1 | G23: =Personal!H23 -> AGENTE RM | H23: 0.3125 | I23: =IF(H23=0," ",IF(Q23=0,(H23+0.417),(H23+0.3756))) -> 16:30 | J23: 0.54166667 | K23: =IF(G23="AGENTE",'Semana 1'!$J23+0.042,IF(G23="REDES",'Semana 1'!$J23+0.042,IF(G23="AGENTE RM",'Semana 1'!$J23+0.042,IF(G23="AGENTE APERTURA",'Semana 1'!$J23+0.021,IF(G23="AGENTE CIERRE",'Semana 1'!$J23+0.021," - "))))) -> 14:00 | L23: 0.34722222 | M23: =IF(G23="AGENTE",'Semana 1'!$L23+0.014,IF(G23="REDES",'Semana 1'!$L23+0.014,IF(G23="AGENTE RM",'Semana 1'!$L23+0.014,IF(G23="AGENTE APERTURA",'Semana 1'!$L23+0.014,IF(G23="AGENTE CIERRE",'Semana 1'!$L23+0.014," - "))))) -> 8:40 | N23: 0.60416667 | O23: =IF(G23="AGENTE",'Semana 1'!$N23+0.007,IF(G23="REDES",'Semana 1'!$N23+0.007,IF(G23="AGENTE RM",'Semana 1'!$N23+0.007,IF(G23="AGENTE APERTURA",'Semana 1'!$N23+0.007,IF(G23="AGENTE CIERRE",'Semana 1'!$N23+0.007," - "))))) -> 14:40 | P23: =(IFERROR(I23-H23,0)*24)-1 -> 8.0 | Q23: 0.375 | R23: =IF(Q23=0,"",Q23+0.209) -> 14:00 | T23: =IF(S23=0,"",S23+0.041) | U23: 0.41666667 | V23: =IF(U23=0,"",U23+0.021) -> 10:30 | X23: =IF(W23=0,"",W23+0.01) | Y23: =(IFERROR(R23-Q23,0)*24) -> 5.0 | Z23: =$P23 -> 8.0 | AA23: =$P23 -> 8.0 | AB23: =$P23 -> 8.0 | AC23: =$P23 -> 8.0 | AD23: =P23+Z23+AA23+AB23+AC23+Y23 -> 45
B24: 19 | C24: Si | E24: =Personal!G24 -> Marcela Alessandra López Melgar | F24: Semana 1 | G24: =Personal!H24 -> REDES | H24: 0.27083333 | I24: =IF(H24=0," ",IF(Q24=0,(H24+0.417),(H24+0.3756))) -> 15:30 | J24: 0.54166667 | K24: =IF(G24="AGENTE",'Semana 1'!$J24+0.042,IF(G24="REDES",'Semana 1'!$J24+0.042,IF(G24="AGENTE RM",'Semana 1'!$J24+0.042,IF(G24="AGENTE APERTURA",'Semana 1'!$J24+0.021,IF(G24="AGENTE CIERRE",'Semana 1'!$J24+0.021," - "))))) -> 14:00 | L24: 0.33333333 | M24: =IF(G24="AGENTE",'Semana 1'!$L24+0.014,IF(G24="REDES",'Semana 1'!$L24+0.014,IF(G24="AGENTE RM",'Semana 1'!$L24+0.014,IF(G24="AGENTE APERTURA",'Semana 1'!$L24+0.014,IF(G24="AGENTE CIERRE",'Semana 1'!$L24+0.014," - "))))) -> 8:20 | N24: 0.58333333 | O24: =IF(G24="AGENTE",'Semana 1'!$N24+0.007,IF(G24="REDES",'Semana 1'!$N24+0.007,IF(G24="AGENTE RM",'Semana 1'!$N24+0.007,IF(G24="AGENTE APERTURA",'Semana 1'!$N24+0.007,IF(G24="AGENTE CIERRE",'Semana 1'!$N24+0.007," - "))))) -> 14:10 | P24: =(IFERROR(I24-H24,0)*24)-1 -> 8.0 | Q24: 0.27083333 | R24: =IF(Q24=0,"",Q24+0.209) -> 11:30 | U24: 0.3125 | V24: =IF(U24=0,"",U24+0.021) -> 8:00 | Y24: =(IFERROR(R24-Q24,0)*24) -> 5.0 | Z24: =$P24 -> 8.0 | AA24: =$P24 -> 8.0 | AB24: =$P24 -> 8.0 | AC24: =$P24 -> 8.0 | AD24: =P24+Z24+AA24+AB24+AC24+Y24 -> 45
B25: 20 | C25: Si | E25: =Personal!G25 -> Ana Marilú González de la Cruz | F25: Semana 1 | G25: =Personal!H25 -> SOPORTE | I25: =IF(H25=0," ",IF(Q25=0,(H25+0.417),(H25+0.3756))) | K25: =IF(G25="AGENTE",'Semana 1'!$J25+0.042,IF(G25="REDES",'Semana 1'!$J25+0.042,IF(G25="AGENTE RM",'Semana 1'!$J25+0.042,IF(G25="AGENTE APERTURA",'Semana 1'!$J25+0.021,IF(G25="AGENTE CIERRE",'Semana 1'!$J25+0.021," - "))))) -> - | M25: =IF(G25="AGENTE",'Semana 1'!$L25+0.014,IF(G25="REDES",'Semana 1'!$L25+0.014,IF(G25="AGENTE RM",'Semana 1'!$L25+0.014,IF(G25="AGENTE APERTURA",'Semana 1'!$L25+0.014,IF(G25="AGENTE CIERRE",'Semana 1'!$L25+0.014," - "))))) -> - | O25: =IF(G25="AGENTE",'Semana 1'!$N25+0.007,IF(G25="REDES",'Semana 1'!$N25+0.007,IF(G25="AGENTE RM",'Semana 1'!$N25+0.007,IF(G25="AGENTE APERTURA",'Semana 1'!$N25+0.007,IF(G25="AGENTE CIERRE",'Semana 1'!$N25+0.007," - "))))) -> - | P25: =(IFERROR(I25-H25,0)*24)-1 -> -1.0 | R25: =IF(Q25=0,"",Q25+0.209) | V25: =IF(U25=0,"",U25+0.021) | Y25: =(IFERROR(R25-Q25,0)*24) -> 0.0 | Z25: =$P25 -> -1.0 | AA25: =$P25 -> -1.0 | AB25: =$P25 -> -1.0 | AC25: =$P25 -> -1.0 | AD25: =P25+Z25+AA25+AB25+AC25+Y25 -> -5
B26: 21 | C26: Si | E26: =Personal!G26 -> Ingrid Rebeca Santizo Lopez | F26: Semana 1 | G26: =Personal!H26 -> AGENTE APERTURA | H26: 0 | I26: 0.29166667 | J26: 0.125 | K26: =IF(G26="AGENTE",'Semana 1'!$J26+0.042,IF(G26="REDES",'Semana 1'!$J26+0.042,IF(G26="AGENTE RM",'Semana 1'!$J26+0.042,IF(G26="AGENTE APERTURA",'Semana 1'!$J26+0.021,IF(G26="AGENTE CIERRE",'Semana 1'!$J26+0.021," - "))))) -> 3:30 | L26: 0.14583333 | M26: =IF(G26="AGENTE",'Semana 1'!$L26+0.014,IF(G26="REDES",'Semana 1'!$L26+0.014,IF(G26="AGENTE RM",'Semana 1'!$L26+0.014,IF(G26="AGENTE APERTURA",'Semana 1'!$L26+0.014,IF(G26="AGENTE CIERRE",'Semana 1'!$L26+0.014," - "))))) -> 3:50 | N26: 0.15972222 | O26: =IF(G26="AGENTE",'Semana 1'!$N26+0.007,IF(G26="REDES",'Semana 1'!$N26+0.007,IF(G26="AGENTE RM",'Semana 1'!$N26+0.007,IF(G26="AGENTE APERTURA",'Semana 1'!$N26+0.007,IF(G26="AGENTE CIERRE",'Semana 1'!$N26+0.007," - "))))) -> 4:00 | P26: =(IFERROR(I26-H26,0)*24)-1 -> 6.0 | Q26: 0 | R26: 0.29166667 | S26: 0.125 | T26: =IF(G26="AGENTE",'Semana 1'!$S26+0.042,IF(G26="REDES",'Semana 1'!$S26+0.042,IF(G26="AGENTE RM",'Semana 1'!$S26+0.042,IF(G26="AGENTE APERTURA",'Semana 1'!$S26+0.021,IF(G26="AGENTE CIERRE",'Semana 1'!$S26+0.021," - "))))) -> 3:30 | U26: 0.14583333 | V26: =IF(G26="AGENTE",'Semana 1'!$U26+0.014,IF(G26="REDES",'Semana 1'!$U26+0.014,IF(G26="AGENTE RM",'Semana 1'!$U26+0.014,IF(G26="AGENTE APERTURA",'Semana 1'!$U26+0.014,IF(G26="AGENTE CIERRE",'Semana 1'!$U26+0.014," - "))))) -> 3:50 | W26: 0.15972222 | X26: =IF(G26="AGENTE",'Semana 1'!$W26+0.007,IF(G26="REDES",'Semana 1'!$W26+0.007,IF(G26="AGENTE RM",'Semana 1'!$W26+0.007,IF(G26="AGENTE APERTURA",'Semana 1'!$W26+0.007,IF(G26="AGENTE CIERRE",'Semana 1'!$W26+0.007," - "))))) -> 4:00 | Y26: =(IFERROR(R26-Q26,0)*24)-1 -> 6.0 | Z26: =$P26 -> 6.0 | AA26: =$P26 -> 6.0 | AB26: =$P26 -> 6.0 | AC26: =$P26 -> 6.0 | AD26: =P26+Z26+AA26+AB26+AC26+Y26 -> 36
B27: 22 | C27: No | E27: =Personal!G27 -> - | F27: Semana 1 | G27: =Personal!H27 -> - | I27: =IF(H27=0," ",IF(Q27=0,(H27+0.417),(H27+0.292))) | K27: =IF(G27="AGENTE",'Semana 1'!$J27+0.042,IF(G27="REDES",'Semana 1'!$J27+0.042,IF(G27="AGENTE RM",'Semana 1'!$J27+0.042,IF(G27="AGENTE APERTURA",'Semana 1'!$J27+0.021,IF(G27="AGENTE CIERRE",'Semana 1'!$J27+0.021," - "))))) -> - | M27: =IF(G27="AGENTE",'Semana 1'!$L27+0.014,IF(G27="REDES",'Semana 1'!$L27+0.014,IF(G27="AGENTE RM",'Semana 1'!$L27+0.014,IF(G27="AGENTE APERTURA",'Semana 1'!$L27+0.014,IF(G27="AGENTE CIERRE",'Semana 1'!$L27+0.014," - "))))) -> - | O27: =IF(G27="AGENTE",'Semana 1'!$N27+0.007,IF(G27="REDES",'Semana 1'!$N27+0.007,IF(G27="AGENTE RM",'Semana 1'!$N27+0.007,IF(G27="AGENTE APERTURA",'Semana 1'!$N27+0.007,IF(G27="AGENTE CIERRE",'Semana 1'!$N27+0.007," - "))))) -> - | P27: =(IFERROR(I27-H27,0)*24)-1 -> -1.0 | R27: =IF(Q27=0," ",IF(Z27=0,(Q27+0.417),(Q27+0.292))) | T27: =IF(S27=0,"",S27+0.041) | V27: =IF(U27=0,"",U27+0.01) | X27: =IF(W27=0,"",W27+0.01) | Y27: =(IFERROR(R27-Q27,0)*24) -> 0.0 | Z27: =$P27 -> -1.0 | AA27: =$P27 -> -1.0 | AB27: =$P27 -> -1.0 | AC27: =$P27 -> -1.0 | AD27: =P27+Z27+AA27+AB27+AC27+Y27 -> -5
B28: 23 | C28: Si | E28: =Personal!G28 -> Byron Abdiel Santos Mejia | F28: Semana 1 | G28: =Personal!H28 -> AGENTE | H28: 0.375 | I28: =IF(H28=0," ",IF(Q28=0,(H28+0.417),(H28+0.3756))) -> 18:00 | J28: 0.625 | K28: =IF(G28="AGENTE",'Semana 1'!$J28+0.042,IF(G28="REDES",'Semana 1'!$J28+0.042,IF(G28="AGENTE RM",'Semana 1'!$J28+0.042,IF(G28="AGENTE APERTURA",'Semana 1'!$J28+0.021,IF(G28="AGENTE CIERRE",'Semana 1'!$J28+0.021," - "))))) -> 16:00 | L28: 0.29166667 | M28: =IF(G28="AGENTE",'Semana 1'!$L28+0.014,IF(G28="REDES",'Semana 1'!$L28+0.014,IF(G28="AGENTE RM",'Semana 1'!$L28+0.014,IF(G28="AGENTE APERTURA",'Semana 1'!$L28+0.014,IF(G28="AGENTE CIERRE",'Semana 1'!$L28+0.014," - "))))) -> 7:20 | N28: 0.71875 | O28: =IF(G28="AGENTE",'Semana 1'!$N28+0.007,IF(G28="REDES",'Semana 1'!$N28+0.007,IF(G28="AGENTE RM",'Semana 1'!$N28+0.007,IF(G28="AGENTE APERTURA",'Semana 1'!$N28+0.007,IF(G28="AGENTE CIERRE",'Semana 1'!$N28+0.007," - "))))) -> 17:25 | P28: =(IFERROR(I28-H28,0)*24)-1 -> 8.0 | Q28: 0.375 | R28: =IF(Q28=0,"",Q28+0.209) -> 14:00 | T28: =IF(S28=0,"",S28+0.041) | U28: 0.37708333 | V28: =IF(U28=0,"",U28+0.01) -> 9:17 | X28: =IF(W28=0,"",W28+0.01) | Y28: =(IFERROR(R28-Q28,0)*24) -> 5.0 | Z28: =$P28 -> 8.0 | AA28: =$P28 -> 8.0 | AB28: =$P28 -> 8.0 | AC28: =$P28 -> 8.0 | AD28: =P28+Z28+AA28+AB28+AC28+Y28 -> 45
B29: 24 | C29: Si | E29: =Personal!G29 -> Karen Lisbeth Vega Ramirez | F29: Semana 1 | G29: =Personal!H29 -> REDES | H29: 0.375 | I29: =IF(H29=0," ",IF(Q29=0,(H29+0.417),(H29+0.3756))) -> 18:00 | J29: 0.5 | K29: =IF(G29="AGENTE",'Semana 1'!$J29+0.042,IF(G29="REDES",'Semana 1'!$J29+0.042,IF(G29="AGENTE RM",'Semana 1'!$J29+0.042,IF(G29="AGENTE APERTURA",'Semana 1'!$J29+0.021,IF(G29="AGENTE CIERRE",'Semana 1'!$J29+0.021," - "))))) -> 13:00 | L29: 0.45833333 | M29: =IF(G29="AGENTE",'Semana 1'!$L29+0.014,IF(G29="REDES",'Semana 1'!$L29+0.014,IF(G29="AGENTE RM",'Semana 1'!$L29+0.014,IF(G29="AGENTE APERTURA",'Semana 1'!$L29+0.014,IF(G29="AGENTE CIERRE",'Semana 1'!$L29+0.014," - "))))) -> 11:20 | N29: 0.65972222 | O29: =IF(G29="AGENTE",'Semana 1'!$N29+0.007,IF(G29="REDES",'Semana 1'!$N29+0.007,IF(G29="AGENTE RM",'Semana 1'!$N29+0.007,IF(G29="AGENTE APERTURA",'Semana 1'!$N29+0.007,IF(G29="AGENTE CIERRE",'Semana 1'!$N29+0.007," - "))))) -> 16:00 | P29: =(IFERROR(I29-H29,0)*24)-1 -> 8.0 | Q29: 0.27083333 | R29: =IF(Q29=0,"",Q29+0.209) -> 11:30 | U29: 0.33333333 | V29: =IF(U29=0,"",U29+0.021) -> 8:30 | Y29: =(IFERROR(R29-Q29,0)*24) -> 5.0 | Z29: =$P29 -> 8.0 | AA29: =$P29 -> 8.0 | AB29: =$P29 -> 8.0 | AC29: =$P29 -> 8.0 | AD29: =P29+Z29+AA29+AB29+AC29+Y29 -> 45
B30: 25 | C30: Si | E30: =Personal!G30 -> Osiris Azucena Leiva Leon | F30: Semana 1 | G30: =Personal!H30 -> AGENTE | H30: 0.29166667 | I30: =IF(H30=0," ",IF(Q30=0,(H30+0.417),(H30+0.3756))) -> 16:00 | J30: 0.5 | K30: =IF(G30="AGENTE",'Semana 1'!$J30+0.042,IF(G30="REDES",'Semana 1'!$J30+0.042,IF(G30="AGENTE RM",'Semana 1'!$J30+0.042,IF(G30="AGENTE APERTURA",'Semana 1'!$J30+0.021,IF(G30="AGENTE CIERRE",'Semana 1'!$J30+0.021," - "))))) -> 13:00 | L30: 0.35416667 | M30: =IF(G30="AGENTE",'Semana 1'!$L30+0.014,IF(G30="REDES",'Semana 1'!$L30+0.014,IF(G30="AGENTE RM",'Semana 1'!$L30+0.014,IF(G30="AGENTE APERTURA",'Semana 1'!$L30+0.014,IF(G30="AGENTE CIERRE",'Semana 1'!$L30+0.014," - "))))) -> 8:50 | N30: 0.65625 | O30: =IF(G30="AGENTE",'Semana 1'!$N30+0.007,IF(G30="REDES",'Semana 1'!$N30+0.007,IF(G30="AGENTE RM",'Semana 1'!$N30+0.007,IF(G30="AGENTE APERTURA",'Semana 1'!$N30+0.007,IF(G30="AGENTE CIERRE",'Semana 1'!$N30+0.007," - "))))) -> 15:55 | P30: =(IFERROR(I30-H30,0)*24)-1 -> 8.0 | Q30: 0.41666667 | R30: =IF(Q30=0,"",Q30+0.209) -> 15:00 | U30: 0.45833333 | V30: =IF(U30=0,"",U30+0.021) -> 11:30 | Y30: =(IFERROR(R30-Q30,0)*24) -> 5.0 | Z30: =$P30 -> 8.0 | AA30: =$P30 -> 8.0 | AB30: =$P30 -> 8.0 | AC30: =$P30 -> 8.0 | AD30: =P30+Z30+AA30+AB30+AC30+Y30 -> 45
B31: 26 | C31: Si | E31: =Personal!G31 -> Gabriela Abigail Guzman Diaz | F31: Semana 1 | G31: =Personal!H31 -> SOPORTE | I31: =IF(H31=0," ",IF(Q31=0,(H31+0.417),(H31+0.3756))) | K31: =IF(G31="AGENTE",'Semana 1'!$J31+0.042,IF(G31="REDES",'Semana 1'!$J31+0.042,IF(G31="AGENTE RM",'Semana 1'!$J31+0.042,IF(G31="AGENTE APERTURA",'Semana 1'!$J31+0.021,IF(G31="AGENTE CIERRE",'Semana 1'!$J31+0.021," - "))))) -> - | M31: =IF(G31="AGENTE",'Semana 1'!$L31+0.014,IF(G31="REDES",'Semana 1'!$L31+0.014,IF(G31="AGENTE RM",'Semana 1'!$L31+0.014,IF(G31="AGENTE APERTURA",'Semana 1'!$L31+0.014,IF(G31="AGENTE CIERRE",'Semana 1'!$L31+0.014," - "))))) -> - | O31: =IF(G31="AGENTE",'Semana 1'!$N31+0.007,IF(G31="REDES",'Semana 1'!$N31+0.007,IF(G31="AGENTE RM",'Semana 1'!$N31+0.007,IF(G31="AGENTE APERTURA",'Semana 1'!$N31+0.007,IF(G31="AGENTE CIERRE",'Semana 1'!$N31+0.007," - "))))) -> - | P31: =(IFERROR(I31-H31,0)*24)-1 -> -1.0 | R31: =IF(Q31=0,"",Q31+0.209) | V31: =IF(U31=0,"",U31+0.021) | Y31: =(IFERROR(R31-Q31,0)*24) -> 0.0 | Z31: =$P31 -> -1.0 | AA31: =$P31 -> -1.0 | AB31: =$P31 -> -1.0 | AC31: =$P31 -> -1.0 | AD31: =P31+Z31+AA31+AB31+AC31+Y31 -> -5
B32: 27 | C32: Si | E32: =Personal!G32 -> Consuelo Magali Herrarte Bautista | F32: Semana 1 | G32: =Personal!H32 -> AGENTE | H32: 0.41666667 | I32: =IF(H32=0," ",IF(Q32=0,(H32+0.417),(H32+0.3756))) -> 19:00 | J32: 0.625 | K32: =IF(G32="AGENTE",'Semana 1'!$J32+0.042,IF(G32="REDES",'Semana 1'!$J32+0.042,IF(G32="AGENTE RM",'Semana 1'!$J32+0.042,IF(G32="AGENTE APERTURA",'Semana 1'!$J32+0.021,IF(G32="AGENTE CIERRE",'Semana 1'!$J32+0.021," - "))))) -> 16:00 | L32: 0.4375 | M32: =IF(G32="AGENTE",'Semana 1'!$L32+0.014,IF(G32="REDES",'Semana 1'!$L32+0.014,IF(G32="AGENTE RM",'Semana 1'!$L32+0.014,IF(G32="AGENTE APERTURA",'Semana 1'!$L32+0.014,IF(G32="AGENTE CIERRE",'Semana 1'!$L32+0.014," - "))))) -> 10:50 | N32: 0.75 | O32: =IF(G32="AGENTE",'Semana 1'!$N32+0.007,IF(G32="REDES",'Semana 1'!$N32+0.007,IF(G32="AGENTE RM",'Semana 1'!$N32+0.007,IF(G32="AGENTE APERTURA",'Semana 1'!$N32+0.007,IF(G32="AGENTE CIERRE",'Semana 1'!$N32+0.007," - "))))) -> 18:10 | P32: =(IFERROR(I32-H32,0)*24)-1 -> 8.0 | Q32: 0.41666667 | R32: =IF(Q32=0,"",Q32+0.209) -> 15:00 | U32: 0.47916667 | V32: =IF(U32=0,"",U32+0.021) -> 12:00 | Y32: =(IFERROR(R32-Q32,0)*24) -> 5.0 | Z32: =$P32 -> 8.0 | AA32: =$P32 -> 8.0 | AB32: =$P32 -> 8.0 | AC32: =$P32 -> 8.0 | AD32: =P32+Z32+AA32+AB32+AC32+Y32 -> 45
B33: 28 | C33: No | E33: =Personal!G33 -> - | F33: Semana 1 | G33: =Personal!H33 -> - | I33: =IF(H33=0," ",IF(Q33=0,(H33+0.417),(H33+0.292))) | K33: =IF(G33="AGENTE",'Semana 1'!$J33+0.042,IF(G33="REDES",'Semana 1'!$J33+0.042,IF(G33="AGENTE RM",'Semana 1'!$J33+0.042,IF(G33="AGENTE APERTURA",'Semana 1'!$J33+0.021,IF(G33="AGENTE CIERRE",'Semana 1'!$J33+0.021," - "))))) -> - | M33: =IF(G33="AGENTE",'Semana 1'!$L33+0.014,IF(G33="REDES",'Semana 1'!$L33+0.014,IF(G33="AGENTE RM",'Semana 1'!$L33+0.014,IF(G33="AGENTE APERTURA",'Semana 1'!$L33+0.014,IF(G33="AGENTE CIERRE",'Semana 1'!$L33+0.014," - "))))) -> - | O33: =IF(G33="AGENTE",'Semana 1'!$N33+0.007,IF(G33="REDES",'Semana 1'!$N33+0.007,IF(G33="AGENTE RM",'Semana 1'!$N33+0.007,IF(G33="AGENTE APERTURA",'Semana 1'!$N33+0.007,IF(G33="AGENTE CIERRE",'Semana 1'!$N33+0.007," - "))))) -> - | P33: =(IFERROR(I33-H33,0)*24)-1 -> -1.0 | R33: =IF(Q33=0," ",IF(Z33=0,(Q33+0.417),(Q33+0.292))) | T33: =IF(S33=0,"",S33+0.041) | V33: =IF(U33=0,"",U33+0.01) | X33: =IF(W33=0,"",W33+0.01) | Y33: =(IFERROR(R33-Q33,0)*24) -> 0.0 | Z33: =$P33 -> -1.0 | AA33: =$P33 -> -1.0 | AB33: =$P33 -> -1.0 | AC33: =$P33 -> -1.0 | AD33: =P33+Z33+AA33+AB33+AC33+Y33 -> -5
B34: 29 | C34: No | E34: =Personal!G34 -> - | F34: Semana 1 | G34: =Personal!H34 -> - | I34: =IF(H34=0," ",IF(Q34=0,(H34+0.417),(H34+0.3756))) | K34: =IF(G34="AGENTE",'Semana 1'!$J34+0.042,IF(G34="REDES",'Semana 1'!$J34+0.042,IF(G34="AGENTE RM",'Semana 1'!$J34+0.042,IF(G34="AGENTE APERTURA",'Semana 1'!$J34+0.021,IF(G34="AGENTE CIERRE",'Semana 1'!$J34+0.021," - "))))) -> - | M34: =IF(G34="AGENTE",'Semana 1'!$L34+0.014,IF(G34="REDES",'Semana 1'!$L34+0.014,IF(G34="AGENTE RM",'Semana 1'!$L34+0.014,IF(G34="AGENTE APERTURA",'Semana 1'!$L34+0.014,IF(G34="AGENTE CIERRE",'Semana 1'!$L34+0.014," - "))))) -> - | O34: =IF(G34="AGENTE",'Semana 1'!$N34+0.007,IF(G34="REDES",'Semana 1'!$N34+0.007,IF(G34="AGENTE RM",'Semana 1'!$N34+0.007,IF(G34="AGENTE APERTURA",'Semana 1'!$N34+0.007,IF(G34="AGENTE CIERRE",'Semana 1'!$N34+0.007," - "))))) -> - | P34: =(IFERROR(I34-H34,0)*24)-1 -> -1.0 | R34: =IF(Q34=0,"",Q34+0.209) | T34: =IF(S34=0,"",S34+0.041) | V34: =IF(U34=0,"",U34+0.01) | X34: =IF(W34=0,"",W34+0.01) | Y34: =(IFERROR(R34-Q34,0)*24) -> 0.0 | Z34: =$P34 -> -1.0 | AA34: =$P34 -> -1.0 | AB34: =$P34 -> -1.0 | AC34: =$P34 -> -1.0 | AD34: =P34+Z34+AA34+AB34+AC34+Y34 -> -5
B35: 30 | C35: Si | E35: =Personal!G35 -> Yoselin Delfina Lucas Juárez | F35: Semana 1 | G35: =Personal!H35 -> REDES | H35: 0.375 | I35: =IF(H35=0," ",IF(Q35=0,(H35+0.417),(H35+0.3756))) -> 18:00 | J35: 0.5 | K35: =IF(G35="AGENTE",'Semana 1'!$J35+0.042,IF(G35="REDES",'Semana 1'!$J35+0.042,IF(G35="AGENTE RM",'Semana 1'!$J35+0.042,IF(G35="AGENTE APERTURA",'Semana 1'!$J35+0.021,IF(G35="AGENTE CIERRE",'Semana 1'!$J35+0.021," - "))))) -> 13:00 | L35: 0.44444444 | M35: =IF(G35="AGENTE",'Semana 1'!$L35+0.014,IF(G35="REDES",'Semana 1'!$L35+0.014,IF(G35="AGENTE RM",'Semana 1'!$L35+0.014,IF(G35="AGENTE APERTURA",'Semana 1'!$L35+0.014,IF(G35="AGENTE CIERRE",'Semana 1'!$L35+0.014," - "))))) -> 11:00 | N35: 0.66666667 | O35: =IF(G35="AGENTE",'Semana 1'!$N35+0.007,IF(G35="REDES",'Semana 1'!$N35+0.007,IF(G35="AGENTE RM",'Semana 1'!$N35+0.007,IF(G35="AGENTE APERTURA",'Semana 1'!$N35+0.007,IF(G35="AGENTE CIERRE",'Semana 1'!$N35+0.007," - "))))) -> 16:10 | P35: =(IFERROR(I35-H35,0)*24)-1 -> 8.0 | Q35: 0.41666667 | R35: =IF(Q35=0,"",Q35+0.209) -> 15:00 | T35: =IF(S35=0,"",S35+0.041) | U35: 0.5 | V35: =IF(U35=0,"",U35+0.01) -> 12:14 | X35: =IF(W35=0,"",W35+0.01) | Y35: =(IFERROR(R35-Q35,0)*24) -> 5.0 | Z35: =$P35 -> 8.0 | AA35: =$P35 -> 8.0 | AB35: =$P35 -> 8.0 | AC35: =$P35 -> 8.0 | AD35: =P35+Z35+AA35+AB35+AC35+Y35 -> 45
B36: 31 | C36: Si | E36: =Personal!G36 -> Marleny Elizabeth Orozco Carrera | F36: Semana 1 | G36: =Personal!H36 -> AGENTE | H36: 0.33333333 | I36: =IF(H36=0," ",IF(Q36=0,(H36+0.417),(H36+0.3756))) -> 17:00 | J36: 0.5625 | K36: =IF(G36="AGENTE",'Semana 1'!$J36+0.042,IF(G36="REDES",'Semana 1'!$J36+0.042,IF(G36="AGENTE RM",'Semana 1'!$J36+0.042,IF(G36="AGENTE APERTURA",'Semana 1'!$J36+0.021,IF(G36="AGENTE CIERRE",'Semana 1'!$J36+0.021," - "))))) -> 14:30 | L36: 0.34375 | M36: =IF(G36="AGENTE",'Semana 1'!$L36+0.014,IF(G36="REDES",'Semana 1'!$L36+0.014,IF(G36="AGENTE RM",'Semana 1'!$L36+0.014,IF(G36="AGENTE APERTURA",'Semana 1'!$L36+0.014,IF(G36="AGENTE CIERRE",'Semana 1'!$L36+0.014," - "))))) -> 8:35 | N36: 0.67708333 | O36: =IF(G36="AGENTE",'Semana 1'!$N36+0.007,IF(G36="REDES",'Semana 1'!$N36+0.007,IF(G36="AGENTE RM",'Semana 1'!$N36+0.007,IF(G36="AGENTE APERTURA",'Semana 1'!$N36+0.007,IF(G36="AGENTE CIERRE",'Semana 1'!$N36+0.007," - "))))) -> 16:25 | P36: =(IFERROR(I36-H36,0)*24)-1 -> 8.0 | Q36: 0.35416667 | R36: =IF(Q36=0,"",Q36+0.209) -> 13:30 | U36: 0.375 | V36: =IF(U36=0,"",U36+0.021) -> 9:30 | Y36: =(IFERROR(R36-Q36,0)*24) -> 5.0 | Z36: =$P36 -> 8.0 | AA36: =$P36 -> 8.0 | AB36: =$P36 -> 8.0 | AC36: =$P36 -> 8.0 | AD36: =P36+Z36+AA36+AB36+AC36+Y36 -> 45
B37: 32 | C37: Si | E37: =Personal!G37 -> Cristian Eduardo Xiloj Zamor | F37: Semana 1 | G37: =Personal!H37 -> AGENTE RM | H37: 0.29166667 | I37: =IF(H37=0," ",IF(Q37=0,(H37+0.417),(H37+0.3756))) -> 16:00 | J37: 0.5 | K37: =IF(G37="AGENTE",'Semana 1'!$J37+0.042,IF(G37="REDES",'Semana 1'!$J37+0.042,IF(G37="AGENTE RM",'Semana 1'!$J37+0.042,IF(G37="AGENTE APERTURA",'Semana 1'!$J37+0.021,IF(G37="AGENTE CIERRE",'Semana 1'!$J37+0.021," - "))))) -> 13:00 | L37: 0.33333333 | M37: =IF(G37="AGENTE",'Semana 1'!$L37+0.014,IF(G37="REDES",'Semana 1'!$L37+0.014,IF(G37="AGENTE RM",'Semana 1'!$L37+0.014,IF(G37="AGENTE APERTURA",'Semana 1'!$L37+0.014,IF(G37="AGENTE CIERRE",'Semana 1'!$L37+0.014," - "))))) -> 8:20 | N37: 0.59375 | O37: =IF(G37="AGENTE",'Semana 1'!$N37+0.007,IF(G37="REDES",'Semana 1'!$N37+0.007,IF(G37="AGENTE RM",'Semana 1'!$N37+0.007,IF(G37="AGENTE APERTURA",'Semana 1'!$N37+0.007,IF(G37="AGENTE CIERRE",'Semana 1'!$N37+0.007," - "))))) -> 14:25 | P37: =(IFERROR(I37-H37,0)*24)-1 -> 8.0 | Q37: 0.29166667 | R37: =IF(Q37=0,"",Q37+0.209) -> 12:00 | U37: 0.35416667 | V37: =IF(U37=0,"",U37+0.021) -> 9:00 | Y37: =(IFERROR(R37-Q37,0)*24) -> 5.0 | Z37: =$P37 -> 8.0 | AA37: =$P37 -> 8.0 | AB37: =$P37 -> 8.0 | AC37: =$P37 -> 8.0 | AD37: =P37+Z37+AA37+AB37+AC37+Y37 -> 45
B38: 33 | C38: No | E38: =Personal!G38 -> - | F38: Semana 1 | G38: =Personal!H38 -> - | I38: =IF(H38=0," ",IF(Q38=0,(H38+0.417),(H38+0.3756))) | K38: =IF(G38="AGENTE",'Semana 1'!$J38+0.042,IF(G38="REDES",'Semana 1'!$J38+0.042,IF(G38="AGENTE RM",'Semana 1'!$J38+0.042,IF(G38="AGENTE APERTURA",'Semana 1'!$J38+0.021,IF(G38="AGENTE CIERRE",'Semana 1'!$J38+0.021," - "))))) -> - | M38: =IF(G38="AGENTE",'Semana 1'!$L38+0.014,IF(G38="REDES",'Semana 1'!$L38+0.014,IF(G38="AGENTE RM",'Semana 1'!$L38+0.014,IF(G38="AGENTE APERTURA",'Semana 1'!$L38+0.014,IF(G38="AGENTE CIERRE",'Semana 1'!$L38+0.014," - "))))) -> - | O38: =IF(G38="AGENTE",'Semana 1'!$N38+0.007,IF(G38="REDES",'Semana 1'!$N38+0.007,IF(G38="AGENTE RM",'Semana 1'!$N38+0.007,IF(G38="AGENTE APERTURA",'Semana 1'!$N38+0.007,IF(G38="AGENTE CIERRE",'Semana 1'!$N38+0.007," - "))))) -> - | P38: =(IFERROR(I38-H38,0)*24)-1 -> -1.0 | R38: =IF(Q38=0,"",Q38+0.209) | V38: =IF(U38=0,"",U38+0.021) | Y38: =(IFERROR(R38-Q38,0)*24) -> 0.0 | Z38: =$P38 -> -1.0 | AA38: =$P38 -> -1.0 | AB38: =$P38 -> -1.0 | AC38: =$P38 -> -1.0 | AD38: =P38+Z38+AA38+AB38+AC38+Y38 -> -5
B39: 34 | C39: Si | E39: =Personal!G39 -> Diego Leonardo Patzan Patzan | F39: Semana 1 | G39: =Personal!H39 -> AGENTE | H39: 0.33333333 | I39: 0.6875 | J39: 0.5 | K39: =IF(G39="AGENTE",'Semana 1'!$J39+0.042,IF(G39="REDES",'Semana 1'!$J39+0.042,IF(G39="AGENTE RM",'Semana 1'!$J39+0.042,IF(G39="AGENTE APERTURA",'Semana 1'!$J39+0.021,IF(G39="AGENTE CIERRE",'Semana 1'!$J39+0.021," - "))))) -> 13:00 | L39: 0.35416667 | M39: =IF(G39="AGENTE",'Semana 1'!$L39+0.014,IF(G39="REDES",'Semana 1'!$L39+0.014,IF(G39="AGENTE RM",'Semana 1'!$L39+0.014,IF(G39="AGENTE APERTURA",'Semana 1'!$L39+0.014,IF(G39="AGENTE CIERRE",'Semana 1'!$L39+0.014," - "))))) -> 8:50 | N39: 0.14583333 | O39: =IF(G39="AGENTE",'Semana 1'!$N39+0.007,IF(G39="REDES",'Semana 1'!$N39+0.007,IF(G39="AGENTE RM",'Semana 1'!$N39+0.007,IF(G39="AGENTE APERTURA",'Semana 1'!$N39+0.007,IF(G39="AGENTE CIERRE",'Semana 1'!$N39+0.007," - "))))) -> 3:40 | P39: =(IFERROR(I39-H39,0)*24)-1 -> 7.5 | Q39: 0.35416667 | R39: 0.66666667 | U39: 0.54166667 | V39: =IF(U39=0,"",U39+0.021) -> 13:30 | Y39: =(IFERROR(R39-Q39,0)*24) -> 7.5 | Z39: =$P39 -> 7.5 | AA39: =$P39 -> 7.5 | AB39: =$P39 -> 7.5 | AC39: =$P39 -> 7.5 | AD39: =P39+Z39+AA39+AB39+AC39+Y39 -> 45
B40: 35 | C40: Si | E40: =Personal!G40 -> Erick Gabriel Velasquez Marroquin | F40: Semana 1 | G40: =Personal!H40 -> AGENTE | H40: 0.375 | I40: =IF(H40=0," ",IF(Q40=0,(H40+0.417),(H40+0.3756))) -> 18:00 | J40: 0.54166667 | K40: =IF(G40="AGENTE",'Semana 1'!$J40+0.042,IF(G40="REDES",'Semana 1'!$J40+0.042,IF(G40="AGENTE RM",'Semana 1'!$J40+0.042,IF(G40="AGENTE APERTURA",'Semana 1'!$J40+0.021,IF(G40="AGENTE CIERRE",'Semana 1'!$J40+0.021," - "))))) -> 14:00 | L40: 0.29166667 | M40: =IF(G40="AGENTE",'Semana 1'!$L40+0.014,IF(G40="REDES",'Semana 1'!$L40+0.014,IF(G40="AGENTE RM",'Semana 1'!$L40+0.014,IF(G40="AGENTE APERTURA",'Semana 1'!$L40+0.014,IF(G40="AGENTE CIERRE",'Semana 1'!$L40+0.014," - "))))) -> 7:20 | N40: 0.67708333 | O40: =IF(G40="AGENTE",'Semana 1'!$N40+0.007,IF(G40="REDES",'Semana 1'!$N40+0.007,IF(G40="AGENTE RM",'Semana 1'!$N40+0.007,IF(G40="AGENTE APERTURA",'Semana 1'!$N40+0.007,IF(G40="AGENTE CIERRE",'Semana 1'!$N40+0.007," - "))))) -> 16:25 | P40: =(IFERROR(I40-H40,0)*24)-1 -> 8.0 | Q40: 0.375 | R40: =IF(Q40=0,"",Q40+0.209) -> 14:00 | T40: =IF(S40=0,"",S40+0.041) | U40: 0.5625 | V40: =IF(U40=0,"",U40+0.021) -> 14:00 | X40: =IF(W40=0,"",W40+0.01) | Y40: =(IFERROR(R40-Q40,0)*24) -> 5.0 | Z40: =$P40 -> 8.0 | AA40: =$P40 -> 8.0 | AB40: =$P40 -> 8.0 | AC40: =$P40 -> 8.0 | AD40: =P40+Z40+AA40+AB40+AC40+Y40 -> 45
...

Sheet Semana 2
P1: lu | Y1: sá
E2: Servicio al cliente
B3: # | C3: Produc | D3: Codigo | E3: Requerimiento | H3: Lunes | Q3: Sabado
E4: Scheduled | H4: Horario | J4: Almuerzo | L4: Break 1 | N4: Break 2 | Q4: Horario | S4: Almuerzo | U4: Break 1 | W4: Break 2
E5: Over / Under | F5: Semana 2 | G5: Skill | H5: 2 Entrada Lunes | I5: 2 Salida Lunes | J5: 2 Inicio Almuerzo Lunes | K5: 2 Termina Almuerzo Lunes | L5: 2 Incio Break 1 Lunes | M5: 2 Termina Break 1 Lunes | N5: 2 Incio Break 2 Lunes | O5: 2 Termina Break 2 Lunes | P5: 2 Horas Lunes | Q5: 2 Entrada Sabado | R5: 2 Salida Sabado | S5: 2 Inicio AlmuerzoSabado | T5: 2 Termina Almuerzo Sabado | U5: 2 Incio Break 1 Sabado | V5: 2 Termina Break 1 Sabado | W5: 2 Incio Break 2 Sabado | X5: 2 Termina Break 2 Sabado | Y5: 2 Horas Sabado | Z5: 2 Horas Martes | AA5: 2 Horas Miercoles | AB5: 2 Horas Jueves | AC5: 2 Horas Viernes | AD5: 2 Horas Semanales
B6: 1 | C6: Si | E6: =Personal!G6 -> Nancy Beatriz Pedroza | F6: Semana 1 | G6: =Personal!H6 -> AGENTE | H6: 0.70833333 | I6: 1 | J6: 0.79166667 | K6: 0.8125 | L6: 0.8125 | M6: =IF(G6="AGENTE",'Semana 1'!$L6+0.014,IF(G6="REDES",'Semana 1'!$L6+0.014,IF(G6="AGENTE RM",'Semana 1'!$L6+0.014,IF(G6="AGENTE APERTURA",'Semana 1'!$L6+0.014,IF(G6="AGENTE CIERRE",'Semana 1'!$L6+0.014," - "))))) -> 19:50 | N6: 0.82638889 | O6: =IF(G6="AGENTE",'Semana 1'!$N6+0.007,IF(G6="REDES",'Semana 1'!$N6+0.007,IF(G6="AGENTE RM",'Semana 1'!$N6+0.007,IF(G6="AGENTE APERTURA",'Semana 1'!$N6+0.007,IF(G6="AGENTE CIERRE",'Semana 1'!$N6+0.007," - "))))) -> 20:00 | P6: =(IFERROR(I6-H6,0)*24)-1 -> 6.0 | Q6: 0.70833333 | R6: 1 | S6: 0.79166667 | T6: 0.8125 | U6: 0.8125 | V6: 0.8265 | W6: 0.82638889 | X6: 0.83338889 | Y6: =(IFERROR(R6-Q6,0)*24)-1 -> 6.0 | Z6: =$P6 -> 6.0 | AA6: =$P6 -> 6.0 | AB6: =$P6 -> 6.0 | AC6: =$P6 -> 6.0 | AD6: =P6+Z6+AA6+AB6+AC6+Y6 -> 36
B7: 2 | C7: Si | E7: =Personal!G7 -> Carina Alejandra Peliz Reban | F7: Semana 1 | G7: =Personal!H7 -> REDES | H7: 0.375 | I7: =IF(H7=0," ",IF(Q7=0,(H7+0.417),(H7+0.3756))) -> 18:00 | J7: 0.5 | K7: =IF(G7="AGENTE",'Semana 1'!$J7+0.042,IF(G7="REDES",'Semana 1'!$J7+0.042,IF(G7="AGENTE RM",'Semana 1'!$J7+0.042,IF(G7="AGENTE APERTURA",'Semana 1'!$J7+0.021,IF(G7="AGENTE CIERRE",'Semana 1'!$J7+0.021," - "))))) -> 13:00 | L7: 0.41666667 | M7: =IF(G7="AGENTE",'Semana 1'!$L7+0.014,IF(G7="REDES",'Semana 1'!$L7+0.014,IF(G7="AGENTE RM",'Semana 1'!$L7+0.014,IF(G7="AGENTE APERTURA",'Semana 1'!$L7+0.014,IF(G7="AGENTE CIERRE",'Semana 1'!$L7+0.014," - "))))) -> 10:20 | N7: 0.64583333 | O7: =IF(G7="AGENTE",'Semana 1'!$N7+0.007,IF(G7="REDES",'Semana 1'!$N7+0.007,IF(G7="AGENTE RM",'Semana 1'!$N7+0.007,IF(G7="AGENTE APERTURA",'Semana 1'!$N7+0.007,IF(G7="AGENTE CIERRE",'Semana 1'!$N7+0.007," - "))))) -> 15:40 | P7: =(IFERROR(I7-H7,0)*24)-1 -> 8.0 | Q7: 0.41666667 | R7: =IF(Q7=0,"",Q7+0.209) -> 15:00 | U7: 0.4375 | V7: =IF(U7=0,"",U7+0.021) -> 11:00 | Y7: =(IFERROR(R7-Q7,0)*24) -> 5.0 | Z7: =$P7 -> 8.0 | AA7: =$P7 -> 8.0 | AB7: =$P7 -> 8.0 | AC7: =$P7 -> 8.0 | AD7: =P7+Z7+AA7+AB7+AC7+Y7 -> 45
B8: 3 | C8: No | E8: =Personal!G8 -> - | F8: Semana 1 | G8: =Personal!H8 -> - | I8: =IF(H8=0," ",IF(Q8=0,(H8+0.417),(H8+0.3756))) | K8: =IF(G8="AGENTE",'Semana 1'!$J8+0.042,IF(G8="REDES",'Semana 1'!$J8+0.042,IF(G8="AGENTE RM",'Semana 1'!$J8+0.042,IF(G8="AGENTE APERTURA",'Semana 1'!$J8+0.021,IF(G8="AGENTE CIERRE",'Semana 1'!$J8+0.021," - "))))) -> - | M8: =IF(G8="AGENTE",'Semana 1'!$L8+0.014,IF(G8="REDES",'Semana 1'!$L8+0.014,IF(G8="AGENTE RM",'Semana 1'!$L8+0.014,IF(G8="AGENTE APERTURA",'Semana 1'!$L8+0.014,IF(G8="AGENTE CIERRE",'Semana 1'!$L8+0.014," - "))))) -> - | O8: =IF(G8="AGENTE",'Semana 1'!$N8+0.007,IF(G8="REDES",'Semana 1'!$N8+0.007,IF(G8="AGENTE RM",'Semana 1'!$N8+0.007,IF(G8="AGENTE APERTURA",'Semana 1'!$N8+0.007,IF(G8="AGENTE CIERRE",'Semana 1'!$N8+0.007," - "))))) -> - | P8: =(IFERROR(I8-H8,0)*24)-1 -> -1.0 | V8: =IF(U8=0,"",U8+0.021) | Y8: =(IFERROR(R8-Q8,0)*24) -> 0.0 | Z8: =$P8 -> -1.0 | AA8: =$P8 -> -1.0 | AB8: =$P8 -> -1.0 | AC8: =$P8 -> -1.0 | AD8: =P8+Z8+AA8+AB8+AC8+Y8 -> -5
B9: 4 | C9: Si | E9: =Personal!G9 -> Daisy Yomara Mateo | F9: Semana 1 | G9: =Personal!H9 -> SOPORTE | I9: =IF(H9=0," ",IF(Q9=0,(H9+0.417),(H9+0.3756))) | K9: =IF(G9="AGENTE",'Semana 1'!$J9+0.042,IF(G9="REDES",'Semana 1'!$J9+0.042,IF(G9="AGENTE RM",'Semana 1'!$J9+0.042,IF(G9="AGENTE APERTURA",'Semana 1'!$J9+0.021,IF(G9="AGENTE CIERRE",'Semana 1'!$J9+0.021," - "))))) -> - | M9: =IF(G9="AGENTE",'Semana 1'!$L9+0.014,IF(G9="REDES",'Semana 1'!$L9+0.014,IF(G9="AGENTE RM",'Semana 1'!$L9+0.014,IF(G9="AGENTE APERTURA",'Semana 1'!$L9+0.014,IF(G9="AGENTE CIERRE",'Semana 1'!$L9+0.014," - "))))) -> - | O9: =IF(G9="AGENTE",'Semana 1'!$N9+0.007,IF(G9="REDES",'Semana 1'!$N9+0.007,IF(G9="AGENTE RM",'Semana 1'!$N9+0.007,IF(G9="AGENTE APERTURA",'Semana 1'!$N9+0.007,IF(G9="AGENTE CIERRE",'Semana 1'!$N9+0.007," - "))))) -> - | P9: =(IFERROR(I9-H9,0)*24)-1 -> -1.0 | R9: =IF(Q9=0,"",Q9+0.209) | V9: =IF(U9=0,"",U9+0.021) | Y9: =(IFERROR(R9-Q9,0)*24) -> 0.0 | Z9: =$P9 -> -1.0 | AA9: =$P9 -> -1.0 | AB9: =$P9 -> -1.0 | AC9: =$P9 -> -1.0 | AD9: =P9+Z9+AA9+AB9+AC9+Y9 -> -5
B10: 5 | C10: Si | E10: =Personal!G10 -> Carlo Giordiano Caballero Morales | F10: Semana 1 | G10: =Personal!H10 -> REDES | H10: 0.29166667 | I10: =IF(H10=0," ",IF(Q10=0,(H10+0.417),(H10+0.3756))) -> 16:00 | J10: 0.54166667 | K10: =IF(G10="AGENTE",'Semana 1'!$J10+0.042,IF(G10="REDES",'Semana 1'!$J10+0.042,IF(G10="AGENTE RM",'Semana 1'!$J10+0.042,IF(G10="AGENTE APERTURA",'Semana 1'!$J10+0.021,IF(G10="AGENTE CIERRE",'Semana 1'!$J10+0.021," - "))))) -> 14:00 | L10: 0.36111111 | M10: =IF(G10="AGENTE",'Semana 1'!$L10+0.014,IF(G10="REDES",'Semana 1'!$L10+0.014,IF(G10="AGENTE RM",'Semana 1'!$L10+0.014,IF(G10="AGENTE APERTURA",'Semana 1'!$L10+0.014,IF(G10="AGENTE CIERRE",'Semana 1'!$L10+0.014," - "))))) -> 9:00 | N10: 0.59722222 | O10: =IF(G10="AGENTE",'Semana 1'!$N10+0.007,IF(G10="REDES",'Semana 1'!$N10+0.007,IF(G10="AGENTE RM",'Semana 1'!$N10+0.007,IF(G10="AGENTE APERTURA",'Semana 1'!$N10+0.007,IF(G10="AGENTE CIERRE",'Semana 1'!$N10+0.007," - "))))) -> 14:30 | P10: =(IFERROR(I10-H10,0)*24)-1 -> 8.0 | Q10: 0.35416667 | R10: =IF(Q10=0,"",Q10+0.209) -> 13:30 | U10: 0.375 | V10: =IF(U10=0,"",U10+0.021) -> 9:30 | Y10: =(IFERROR(R10-Q10,0)*24) -> 5.0 | Z10: =$P10 -> 8.0 | AA10: =$P10 -> 8.0 | AB10: =$P10 -> 8.0 | AC10: =$P10 -> 8.0 | AD10: =P10+Z10+AA10+AB10+AC10+Y10 -> 45
B11: 6 | C11: Si | E11: =Personal!G11 -> Ani Rubi Lucero Gonzalez | F11: Semana 1 | G11: =Personal!H11 -> SOPORTE | I11: =IF(H11=0," ",IF(Q11=0,(H11+0.417),(H11+0.3756))) | K11: =IF(G11="AGENTE",'Semana 1'!$J11+0.042,IF(G11="REDES",'Semana 1'!$J11+0.042,IF(G11="AGENTE RM",'Semana 1'!$J11+0.042,IF(G11="AGENTE APERTURA",'Semana 1'!$J11+0.021,IF(G11="AGENTE CIERRE",'Semana 1'!$J11+0.021," - "))))) -> - | M11: =IF(G11="AGENTE",'Semana 1'!$L11+0.014,IF(G11="REDES",'Semana 1'!$L11+0.014,IF(G11="AGENTE RM",'Semana 1'!$L11+0.014,IF(G11="AGENTE APERTURA",'Semana 1'!$L11+0.014,IF(G11="AGENTE CIERRE",'Semana 1'!$L11+0.014," - "))))) -> - | O11: =IF(G11="AGENTE",'Semana 1'!$N11+0.007,IF(G11="REDES",'Semana 1'!$N11+0.007,IF(G11="AGENTE RM",'Semana 1'!$N11+0.007,IF(G11="AGENTE APERTURA",'Semana 1'!$N11+0.007,IF(G11="AGENTE CIERRE",'Semana 1'!$N11+0.007," - "))))) -> - | P11: =(IFERROR(I11-H11,0)*24)-1 -> -1.0 | R11: =IF(Q11=0,"",Q11+0.209) | Y11: =(IFERROR(R11-Q11,0)*24) -> 0.0 | Z11: =$P11 -> -1.0 | AA11: =$P11 -> -1.0 | AB11: =$P11 -> -1.0 | AC11: =$P11 -> -1.0 | AD11: =P11+Z11+AA11+AB11+AC11+Y11 -> -5
B12: 7 | C12: Si | E12: =Personal!G12 -> Hilda Sofia Gonzalez De León | F12: Semana 1 | G12: =Personal!H12 -> REDES | H12: 0.375 | I12: =IF(H12=0," ",IF(Q12=0,(H12+0.417),(H12+0.3756))) -> 18:00 | J12: 0.5 | K12: =IF(G12="AGENTE",'Semana 1'!$J12+0.042,IF(G12="REDES",'Semana 1'!$J12+0.042,IF(G12="AGENTE RM",'Semana 1'!$J12+0.042,IF(G12="AGENTE APERTURA",'Semana 1'!$J12+0.021,IF(G12="AGENTE CIERRE",'Semana 1'!$J12+0.021," - "))))) -> 13:00 | L12: 0.43055556 | M12: =IF(G12="AGENTE",'Semana 1'!$L12+0.014,IF(G12="REDES",'Semana 1'!$L12+0.014,IF(G12="AGENTE RM",'Semana 1'!$L12+0.014,IF(G12="AGENTE APERTURA",'Semana 1'!$L12+0.014,IF(G12="AGENTE CIERRE",'Semana 1'!$L12+0.014," - "))))) -> 10:40 | N12: 0.65277778 | O12: =IF(G12="AGENTE",'Semana 1'!$N12+0.007,IF(G12="REDES",'Semana 1'!$N12+0.007,IF(G12="AGENTE RM",'Semana 1'!$N12+0.007,IF(G12="AGENTE APERTURA",'Semana 1'!$N12+0.007,IF(G12="AGENTE CIERRE",'Semana 1'!$N12+0.007," - "))))) -> 15:50 | P12: =(IFERROR(I12-H12,0)*24)-1 -> 8.0 | Q12: 0.375 | R12: =IF(Q12=0,"",Q12+0.209) -> 14:00 | U12: 0.39583333 | V12: =IF(U12=0,"",U12+0.021) -> 10:00 | Y12: =(IFERROR(R12-Q12,0)*24) -> 5.0 | Z12: =$P12 -> 8.0 | AA12: =$P12 -> 8.0 | AB12: =$P12 -> 8.0 | AC12: =$P12 -> 8.0 | AD12: =P12+Z12+AA12+AB12+AC12+Y12 -> 45
B13: 8 | C13: No | E13: =Personal!G13 -> - | F13: Semana 1 | G13: =Personal!H13 -> - | I13: =IF(H13=0," ",IF(Q13=0,(H13+0.417),(H13+0.3756))) | K13: =IF(G13="AGENTE",'Semana 1'!$J13+0.042,IF(G13="REDES",'Semana 1'!$J13+0.042,IF(G13="AGENTE RM",'Semana 1'!$J13+0.042,IF(G13="AGENTE APERTURA",'Semana 1'!$J13+0.021,IF(G13="AGENTE CIERRE",'Semana 1'!$J13+0.021," - "))))) -> - | M13: =IF(G13="AGENTE",'Semana 1'!$L13+0.014,IF(G13="REDES",'Semana 1'!$L13+0.014,IF(G13="AGENTE RM",'Semana 1'!$L13+0.014,IF(G13="AGENTE APERTURA",'Semana 1'!$L13+0.014,IF(G13="AGENTE CIERRE",'Semana 1'!$L13+0.014," - "))))) -> - | O13: =IF(G13="AGENTE",'Semana 1'!$N13+0.007,IF(G13="REDES",'Semana 1'!$N13+0.007,IF(G13="AGENTE RM",'Semana 1'!$N13+0.007,IF(G13="AGENTE APERTURA",'Semana 1'!$N13+0.007,IF(G13="AGENTE CIERRE",'Semana 1'!$N13+0.007," - "))))) -> - | P13: =(IFERROR(I13-H13,0)*24)-1 -> -1.0 | R13: =IF(Q13=0,"",Q13+0.209) | V13: =IF(U13=0,"",U13+0.021) | Y13: =(IFERROR(R13-Q13,0)*24) -> 0.0 | Z13: =$P13 -> -1.0 | AA13: =$P13 -> -1.0 | AB13: =$P13 -> -1.0 | AC13: =$P13 -> -1.0 | AD13: =P13+Z13+AA13+AB13+AC13+Y13 -> -5
B14: 9 | C14: Si | E14: =Personal!G14 -> Jorge Israel Reyes Valencia | F14: Semana 1 | G14: =Personal!H14 -> SOPORTE | I14: =IF(H14=0," ",IF(Q14=0,(H14+0.417),(H14+0.3756))) | K14: =IF(G14="AGENTE",'Semana 1'!$J14+0.042,IF(G14="REDES",'Semana 1'!$J14+0.042,IF(G14="AGENTE RM",'Semana 1'!$J14+0.042,IF(G14="AGENTE APERTURA",'Semana 1'!$J14+0.021,IF(G14="AGENTE CIERRE",'Semana 1'!$J14+0.021," - "))))) -> - | M14: =IF(G14="AGENTE",'Semana 1'!$L14+0.014,IF(G14="REDES",'Semana 1'!$L14+0.014,IF(G14="AGENTE RM",'Semana 1'!$L14+0.014,IF(G14="AGENTE APERTURA",'Semana 1'!$L14+0.014,IF(G14="AGENTE CIERRE",'Semana 1'!$L14+0.014," - "))))) -> - | O14: =IF(G14="AGENTE",'Semana 1'!$N14+0.007,IF(G14="REDES",'Semana 1'!$N14+0.007,IF(G14="AGENTE RM",'Semana 1'!$N14+0.007,IF(G14="AGENTE APERTURA",'Semana 1'!$N14+0.007,IF(G14="AGENTE CIERRE",'Semana 1'!$N14+0.007," - "))))) -> - | P14: =(IFERROR(I14-H14,0)*24)-1 -> -1.0 | R14: =IF(Q14=0,"",Q14+0.209) | T14: =IF(S14=0,"",S14+0.021) | V14: =IF(U14=0,"",U14+0.01) | X14: =IF(W14=0,"",W14+0.01) | Y14: =(IFERROR(R14-Q14,0)*24) -> 0.0 | Z14: =$P14 -> -1.0 | AA14: =$P14 -> -1.0 | AB14: =$P14 -> -1.0 | AC14: =$P14 -> -1.0 | AD14: =P14+Z14+AA14+AB14+AC14+Y14 -> -5
B15: 10 | C15: Si | E15: =Personal!G15 -> Marcos Geovanny Coronado Giron | F15: Semana 1 | G15: =Personal!H15 -> SOPORTE | I15: =IF(H15=0," ",IF(Q15=0,(H15+0.417),(H15+0.3756))) | K15: =IF(G15="AGENTE",'Semana 1'!$J15+0.042,IF(G15="REDES",'Semana 1'!$J15+0.042,IF(G15="AGENTE RM",'Semana 1'!$J15+0.042,IF(G15="AGENTE APERTURA",'Semana 1'!$J15+0.021,IF(G15="AGENTE CIERRE",'Semana 1'!$J15+0.021," - "))))) -> - | M15: =IF(G15="AGENTE",'Semana 1'!$L15+0.014,IF(G15="REDES",'Semana 1'!$L15+0.014,IF(G15="AGENTE RM",'Semana 1'!$L15+0.014,IF(G15="AGENTE APERTURA",'Semana 1'!$L15+0.014,IF(G15="AGENTE CIERRE",'Semana 1'!$L15+0.014," - "))))) -> - | O15: =IF(G15="AGENTE",'Semana 1'!$N15+0.007,IF(G15="REDES",'Semana 1'!$N15+0.007,IF(G15="AGENTE RM",'Semana 1'!$N15+0.007,IF(G15="AGENTE APERTURA",'Semana 1'!$N15+0.007,IF(G15="AGENTE CIERRE",'Semana 1'!$N15+0.007," - "))))) -> - | P15: =(IFERROR(I15-H15,0)*24)-1 -> -1.0 | R15: =IF(Q15=0,"",Q15+0.209) | Y15: =(IFERROR(R15-Q15,0)*24) -> 0.0 | Z15: =$P15 -> -1.0 | AA15: =$P15 -> -1.0 | AB15: =$P15 -> -1.0 | AC15: =$P15 -> -1.0 | AD15: =P15+Z15+AA15+AB15+AC15+Y15 -> -5
B16: 11 | C16: Si | E16: =Personal!G16 -> Anyely Eunice Florian Florian | F16: Semana 1 | G16: =Personal!H16 -> SOPORTE | I16: =IF(H16=0," ",IF(Q16=0,(H16+0.417),(H16+0.3756))) | K16: =IF(G16="AGENTE",'Semana 1'!$J16+0.042,IF(G16="REDES",'Semana 1'!$J16+0.042,IF(G16="AGENTE RM",'Semana 1'!$J16+0.042,IF(G16="AGENTE APERTURA",'Semana 1'!$J16+0.021,IF(G16="AGENTE CIERRE",'Semana 1'!$J16+0.021," - "))))) -> - | M16: =IF(G16="AGENTE",'Semana 1'!$L16+0.014,IF(G16="REDES",'Semana 1'!$L16+0.014,IF(G16="AGENTE RM",'Semana 1'!$L16+0.014,IF(G16="AGENTE APERTURA",'Semana 1'!$L16+0.014,IF(G16="AGENTE CIERRE",'Semana 1'!$L16+0.014," - "))))) -> - | O16: =IF(G16="AGENTE",'Semana 1'!$N16+0.007,IF(G16="REDES",'Semana 1'!$N16+0.007,IF(G16="AGENTE RM",'Semana 1'!$N16+0.007,IF(G16="AGENTE APERTURA",'Semana 1'!$N16+0.007,IF(G16="AGENTE CIERRE",'Semana 1'!$N16+0.007," - "))))) -> - | P16: =(IFERROR(I16-H16,0)*24)-1 -> -1.0 | R16: =IF(Q16=0,"",Q16+0.209) | V16: =IF(U16=0,"",U16+0.021) | X16: =IF(W16=0,"",W16+0.021) | Y16: =(IFERROR(R16-Q16,0)*24) -> 0.0 | Z16: =$P16 -> -1.0 | AA16: =$P16 -> -1.0 | AB16: =$P16 -> -1.0 | AC16: =$P16 -> -1.0 | AD16: =P16+Z16+AA16+AB16+AC16+Y16 -> -5
B17: 12 | C17: Si | E17: =Personal!G17 -> Jennifer Alicia Boror Rodriguez | F17: Semana 1 | G17: =Personal!H17 -> REDES | H17: 0.27083333 | I17: =IF(H17=0," ",IF(Q17=0,(H17+0.417),(H17+0.3756))) -> 15:30 | J17: 0.54166667 | K17: =IF(G17="AGENTE",'Semana 1'!$J17+0.042,IF(G17="REDES",'Semana 1'!$J17+0.042,IF(G17="AGENTE RM",'Semana 1'!$J17+0.042,IF(G17="AGENTE APERTURA",'Semana 1'!$J17+0.021,IF(G17="AGENTE CIERRE",'Semana 1'!$J17+0.021," - "))))) -> 14:00 | L17: 0.34722222 | M17: =IF(G17="AGENTE",'Semana 1'!$L17+0.014,IF(G17="REDES",'Semana 1'!$L17+0.014,IF(G17="AGENTE RM",'Semana 1'!$L17+0.014,IF(G17="AGENTE APERTURA",'Semana 1'!$L17+0.014,IF(G17="AGENTE CIERRE",'Semana 1'!$L17+0.014," - "))))) -> 8:40 | N17: 0.59027778 | O17: =IF(G17="AGENTE",'Semana 1'!$N17+0.007,IF(G17="REDES",'Semana 1'!$N17+0.007,IF(G17="AGENTE RM",'Semana 1'!$N17+0.007,IF(G17="AGENTE APERTURA",'Semana 1'!$N17+0.007,IF(G17="AGENTE CIERRE",'Semana 1'!$N17+0.007," - "))))) -> 14:20 | P17: =(IFERROR(I17-H17,0)*24)-1 -> 8.0 | Q17: 0.27083333 | R17: =IF(Q17=0,"",Q17+0.209) -> 11:30 | U17: 0.3125 | V17: =IF(U17=0,"",U17+0.021) -> 8:00 | Y17: =(IFERROR(R17-Q17,0)*24) -> 5.0 | Z17: =$P17 -> 8.0 | AA17: =$P17 -> 8.0 | AB17: =$P17 -> 8.0 | AC17: =$P17 -> 8.0 | AD17: =P17+Z17+AA17+AB17+AC17+Y17 -> 45
B18: 13 | C18: No | E18: =Personal!G18 -> - | F18: Semana 1 | G18: =Personal!H18 -> - | I18: =IF(H18=0," ",IF(Q18=0,(H18+0.417),(H18+0.3756))) | K18: =IF(G18="AGENTE",'Semana 1'!$J18+0.042,IF(G18="REDES",'Semana 1'!$J18+0.042,IF(G18="AGENTE RM",'Semana 1'!$J18+0.042,IF(G18="AGENTE APERTURA",'Semana 1'!$J18+0.021,IF(G18="AGENTE CIERRE",'Semana 1'!$J18+0.021," - "))))) -> - | M18: =IF(G18="AGENTE",'Semana 1'!$L18+0.014,IF(G18="REDES",'Semana 1'!$L18+0.014,IF(G18="AGENTE RM",'Semana 1'!$L18+0.014,IF(G18="AGENTE APERTURA",'Semana 1'!$L18+0.014,IF(G18="AGENTE CIERRE",'Semana 1'!$L18+0.014," - "))))) -> - | O18: =IF(G18="AGENTE",'Semana 1'!$N18+0.007,IF(G18="REDES",'Semana 1'!$N18+0.007,IF(G18="AGENTE RM",'Semana 1'!$N18+0.007,IF(G18="AGENTE APERTURA",'Semana 1'!$N18+0.007,IF(G18="AGENTE CIERRE",'Semana 1'!$N18+0.007," - "))))) -> - | P18: =(IFERROR(I18-H18,0)*24)-1 -> -1.0 | R18: =IF(Q18=0,"",Q18+0.209) | V18: =IF(U18=0,"",U18+0.021) | Y18: =(IFERROR(R18-Q18,0)*24) -> 0.0 | Z18: =$P18 -> -1.0 | AA18: =$P18 -> -1.0 | AB18: =$P18 -> -1.0 | AC18: =$P18 -> -1.0 | AD18: =P18+Z18+AA18+AB18+AC18+Y18 -> -5
